Workbook
Name CODE: 'Point Matrix'!$A$2:$A$41
Name FPTS: 'Point Matrix'!$B$2:$B$41
Name GPTS: 'Point Matrix'!$C$2:$C$40

Sheet BAL - Projections
A1: FLEX | B1: RuTD | C1: ReTD | D1: 2PC/S | E1: PaTD | F1: RuY | G1: Re | H1: ReY | I1: 2PC/P | J1: INT | K1: FU/L | L1: FR | M1: PaY | N1: 300+ PaY Gm | O1: 100+ RuY GM | P1: 100+ ReY GM | Q1: Game Points | R1: Fantasy Points
A2: QB:BAL | N2: =IF(M2>=300,1,0) -> 0 | O2: =IF(F2>=100,1,0) -> 0 | P2: =IF(H2>=100,1,0) -> 0 | Q2: =SUM(B2*INDEX(GPTS,MATCH($B$1,CODE,0)),C2*INDEX(GPTS,MATCH($C$1,CODE,0)),D2*INDEX(GPTS,MATCH($D$1,CODE,0))) -> 0 | R2: =SUM(B2*INDEX(FPTS,MATCH($B$1,CODE,0)),C2*INDEX(FPTS,MATCH($C$1,CODE,0)),D2*INDEX(FPTS,MATCH($D$1,CODE,0)),E2*INDEX(FPTS,MATCH($E$1,CODE,0)),F2*INDEX(FPTS,MATCH($F$1,CODE,0)),G2*INDEX(FPTS,MATCH($G$1,CODE,0)),H2*INDEX(FPTS,MATCH($H$1,CODE,0)),I2*INDEX(FPTS,MATCH($I$1,CODE,0)),J2*INDEX(FPTS,MATCH($J$1,CODE,0)),K2*INDEX(FPTS,MATCH($K$1,CODE,0)),L2*INDEX(FPTS,MATCH($L$1,CODE,0)),M2*INDEX(FPTS,MATCH($M$1,CODE,0)),N2*INDEX(FPTS,MATCH($N$1,CODE,0)),O2*INDEX(FPTS,MATCH($P$1,CODE,0)),P2*INDEX(FPTS,MATCH($O$1,CODE,0))) -> 0
A3: RB:BAL | N3: =IF(M3>=300,1,0) -> 0 | O3: =IF(F3>=100,1,0) -> 0 | P3: =IF(H3>=100,1,0) -> 0 | Q3: =SUM(B3*INDEX(GPTS,MATCH($B$1,CODE,0)),C3*INDEX(GPTS,MATCH($C$1,CODE,0)),D3*INDEX(GPTS,MATCH($D$1,CODE,0))) -> 0 | R3: =SUM(B3*INDEX(FPTS,MATCH($B$1,CODE,0)),C3*INDEX(FPTS,MATCH($C$1,CODE,0)),D3*INDEX(FPTS,MATCH($D$1,CODE,0)),E3*INDEX(FPTS,MATCH($E$1,CODE,0)),F3*INDEX(FPTS,MATCH($F$1,CODE,0)),G3*INDEX(FPTS,MATCH($G$1,CODE,0)),H3*INDEX(FPTS,MATCH($H$1,CODE,0)),I3*INDEX(FPTS,MATCH($I$1,CODE,0)),J3*INDEX(FPTS,MATCH($J$1,CODE,0)),K3*INDEX(FPTS,MATCH($K$1,CODE,0)),L3*INDEX(FPTS,MATCH($L$1,CODE,0)),M3*INDEX(FPTS,MATCH($M$1,CODE,0)),N3*INDEX(FPTS,MATCH($N$1,CODE,0)),O3*INDEX(FPTS,MATCH($P$1,CODE,0)),P3*INDEX(FPTS,MATCH($O$1,CODE,0))) -> 0
A4: TE:BAL | N4: =IF(M4>=300,1,0) -> 0 | O4: =IF(F4>=100,1,0) -> 0 | P4: =IF(H4>=100,1,0) -> 0 | Q4: =SUM(B4*INDEX(GPTS,MATCH($B$1,CODE,0)),C4*INDEX(GPTS,MATCH($C$1,CODE,0)),D4*INDEX(GPTS,MATCH($D$1,CODE,0))) -> 0 | R4: =SUM(B4*INDEX(FPTS,MATCH($B$1,CODE,0)),C4*INDEX(FPTS,MATCH($C$1,CODE,0)),D4*INDEX(FPTS,MATCH($D$1,CODE,0)),E4*INDEX(FPTS,MATCH($E$1,CODE,0)),F4*INDEX(FPTS,MATCH($F$1,CODE,0)),G4*INDEX(FPTS,MATCH($G$1,CODE,0)),H4*INDEX(FPTS,MATCH($H$1,CODE,0)),I4*INDEX(FPTS,MATCH($I$1,CODE,0)),J4*INDEX(FPTS,MATCH($J$1,CODE,0)),K4*INDEX(FPTS,MATCH($K$1,CODE,0)),L4*INDEX(FPTS,MATCH($L$1,CODE,0)),M4*INDEX(FPTS,MATCH($M$1,CODE,0)),N4*INDEX(FPTS,MATCH($N$1,CODE,0)),O4*INDEX(FPTS,MATCH($P$1,CODE,0)),P4*INDEX(FPTS,MATCH($O$1,CODE,0))) -> 0
A5: WR1:BAL | N5: =IF(M5>=300,1,0) -> 0 | O5: =IF(F5>=100,1,0) -> 0 | P5: =IF(H5>=100,1,0) -> 0 | Q5: =SUM(B5*INDEX(GPTS,MATCH($B$1,CODE,0)),C5*INDEX(GPTS,MATCH($C$1,CODE,0)),D5*INDEX(GPTS,MATCH($D$1,CODE,0))) -> 0 | R5: =SUM(B5*INDEX(FPTS,MATCH($B$1,CODE,0)),C5*INDEX(FPTS,MATCH($C$1,CODE,0)),D5*INDEX(FPTS,MATCH($D$1,CODE,0)),E5*INDEX(FPTS,MATCH($E$1,CODE,0)),F5*INDEX(FPTS,MATCH($F$1,CODE,0)),G5*INDEX(FPTS,MATCH($G$1,CODE,0)),H5*INDEX(FPTS,MATCH($H$1,CODE,0)),I5*INDEX(FPTS,MATCH($I$1,CODE,0)),J5*INDEX(FPTS,MATCH($J$1,CODE,0)),K5*INDEX(FPTS,MATCH($K$1,CODE,0)),L5*INDEX(FPTS,MATCH($L$1,CODE,0)),M5*INDEX(FPTS,MATCH($M$1,CODE,0)),N5*INDEX(FPTS,MATCH($N$1,CODE,0)),O5*INDEX(FPTS,MATCH($P$1,CODE,0)),P5*INDEX(FPTS,MATCH($O$1,CODE,0))) -> 0
A6: WR2:BAL | N6: =IF(M6>=300,1,0) -> 0 | O6: =IF(F6>=100,1,0) -> 0 | P6: =IF(H6>=100,1,0) -> 0 | Q6: =SUM(B6*INDEX(GPTS,MATCH($B$1,CODE,0)),C6*INDEX(GPTS,MATCH($C$1,CODE,0)),D6*INDEX(GPTS,MATCH($D$1,CODE,0))) -> 0 | R6: =SUM(B6*INDEX(FPTS,MATCH($B$1,CODE,0)),C6*INDEX(FPTS,MATCH($C$1,CODE,0)),D6*INDEX(FPTS,MATCH($D$1,CODE,0)),E6*INDEX(FPTS,MATCH($E$1,CODE,0)),F6*INDEX(FPTS,MATCH($F$1,CODE,0)),G6*INDEX(FPTS,MATCH($G$1,CODE,0)),H6*INDEX(FPTS,MATCH($H$1,CODE,0)),I6*INDEX(FPTS,MATCH($I$1,CODE,0)),J6*INDEX(FPTS,MATCH($J$1,CODE,0)),K6*INDEX(FPTS,MATCH($K$1,CODE,0)),L6*INDEX(FPTS,MATCH($L$1,CODE,0)),M6*INDEX(FPTS,MATCH($M$1,CODE,0)),N6*INDEX(FPTS,MATCH($N$1,CODE,0)),O6*INDEX(FPTS,MATCH($P$1,CODE,0)),P6*INDEX(FPTS,MATCH($O$1,CODE,0))) -> 0
A7: WR3:BAL | N7: =IF(M7>=300,1,0) -> 0 | O7: =IF(F7>=100,1,0) -> 0 | P7: =IF(H7>=100,1,0) -> 0 | Q7: =SUM(B7*INDEX(GPTS,MATCH($B$1,CODE,0)),C7*INDEX(GPTS,MATCH($C$1,CODE,0)),D7*INDEX(GPTS,MATCH($D$1,CODE,0))) -> 0 | R7: =SUM(B7*INDEX(FPTS,MATCH($B$1,CODE,0)),C7*INDEX(FPTS,MATCH($C$1,CODE,0)),D7*INDEX(FPTS,MATCH($D$1,CODE,0)),E7*INDEX(FPTS,MATCH($E$1,CODE,0)),F7*INDEX(FPTS,MATCH($F$1,CODE,0)),G7*INDEX(FPTS,MATCH($G$1,CODE,0)),H7*INDEX(FPTS,MATCH($H$1,CODE,0)),I7*INDEX(FPTS,MATCH($I$1,CODE,0)),J7*INDEX(FPTS,MATCH($J$1,CODE,0)),K7*INDEX(FPTS,MATCH($K$1,CODE,0)),L7*INDEX(FPTS,MATCH($L$1,CODE,0)),M7*INDEX(FPTS,MATCH($M$1,CODE,0)),N7*INDEX(FPTS,MATCH($N$1,CODE,0)),O7*INDEX(FPTS,MATCH($P$1,CODE,0)),P7*INDEX(FPTS,MATCH($O$1,CODE,0))) -> 0
A9: D | B9: DE/RTD | C9: DE/SF | D9: DE/XPR | E9: FR | F9: DE/I | G9: S | H9: DE/B | I9: DE/PA0 | J9: DE/PA1-6 | K9: DE/PA7-13 | L9: DE/PA14-20 | M9: DE/PA28-34 | N9: DE/PA35+
A10: D:BAL | I10: =IF('BUF - Projections'!Q15=0,1,0) -> 1 | J10: =IF(AND('BUF - Projections'!Q15>0,'BUF - Projections'!Q15<7),1,0) -> 0 | K10: =IF(AND('BUF - Projections'!Q15>6,'BUF - Projections'!Q15<14),1,0) -> 0 | L10: =IF(AND('BUF - Projections'!Q15>13,'BUF - Projections'!Q15<21),1,0) -> 0 | M10: =IF(AND('BUF - Projections'!Q15>27,'BUF - Projections'!Q15<35),1,0) -> 0 | N10: =IF('BUF - Projections'!Q15>35,1,0) -> 0 | Q10: =SUM(B10*INDEX(GPTS,MATCH($B$9,CODE,0)),C10*INDEX(GPTS,MATCH($C$9,CODE,0)),D10*INDEX(GPTS,MATCH($D$9,CODE,0))) -> 0 | R10: =SUM(B10*INDEX(FPTS,MATCH($B$9,CODE,0)),C10*INDEX(FPTS,MATCH($C$9,CODE,0)),D10*INDEX(FPTS,MATCH($D$9,CODE,0)),E10*INDEX(FPTS,MATCH($E$9,CODE,0)),F10*INDEX(FPTS,MATCH($F$9,CODE,0)),G10*INDEX(FPTS,MATCH($G$9,CODE,0)),H10*INDEX(FPTS,MATCH($H$9,CODE,0)),I10*INDEX(FPTS,MATCH($I$9,CODE,0)),J10*INDEX(FPTS,MATCH($J$9,CODE,0)),K10*INDEX(FPTS,MATCH($K$9,CODE,0)),L10*INDEX(FPTS,MATCH($L$9,CODE,0)),M10*INDEX(FPTS,MATCH($M$9,CODE,0)),N10*INDEX(FPTS,MATCH($N$9,CODE,0))) -> 10
A12: K | B12: FGu20 | C12: FGu30 | D12: FGu40 | E12: FGu50 | F12: FGo50 | G12: XP | H12: 2PC/S | I12: 2PC/P | J12: FU/L
A13: K:BAL | Q13: =SUM(B13*INDEX(GPTS,MATCH($B$12,CODE,0)),C13*INDEX(GPTS,MATCH($C$12,CODE,0)),D13*INDEX(GPTS,MATCH($D$12,CODE,0)),E13*INDEX(GPTS,MATCH($E$12,CODE,0)),F13*INDEX(GPTS,MATCH($F$12,CODE,0)),G13*INDEX(GPTS,MATCH($G$12,CODE,0)),H13*INDEX(GPTS,MATCH($H$12,CODE,0)),I13*INDEX(GPTS,MATCH($I$12,CODE,0)),J13*INDEX(GPTS,MATCH($J$12,CODE,0))) -> 0 | R13: =SUM(B13*INDEX(FPTS,MATCH($B$12,CODE,0)),C13*INDEX(FPTS,MATCH($C$12,CODE,0)),D13*INDEX(FPTS,MATCH($D$12,CODE,0)),E13*INDEX(FPTS,MATCH($E$12,CODE,0)),F13*INDEX(FPTS,MATCH($F$12,CODE,0)),G13*INDEX(FPTS,MATCH($G$12,CODE,0)),H13*INDEX(FPTS,MATCH($H$12,CODE,0)),I13*INDEX(FPTS,MATCH($I$12,CODE,0)),J13*INDEX(FPTS,MATCH($J$12,CODE,0))) -> 0
A15: TOTALS | Q15: =SUM(Q1:Q13) -> 0 | R15: =SUM(R1:R13) -> 10

Sheet BUF - Projections
A1: FLEX | B1: RuTD | C1: ReTD | D1: 2PC/S | E1: PaTD | F1: RuY | G1: Re | H1: ReY | I1: 2PC/P | J1: INT | K1: FU/L | L1: FR | M1: PaY | N1: 300+ PaY Gm | O1: 100+ RuY GM | P1: 100+ ReY GM | Q1: Game Points | R1: Fantasy Points
A2: QB:BUF | N2: =IF(M2>=300,1,0) -> 0 | O2: =IF(F2>=100,1,0) -> 0 | P2: =IF(H2>=100,1,0) -> 0 | Q2: =SUM(B2*INDEX(GPTS,MATCH($B$1,CODE,0)),C2*INDEX(GPTS,MATCH($C$1,CODE,0)),D2*INDEX(GPTS,MATCH($D$1,CODE,0))) -> 0 | R2: =SUM(B2*INDEX(FPTS,MATCH($B$1,CODE,0)),C2*INDEX(FPTS,MATCH($C$1,CODE,0)),D2*INDEX(FPTS,MATCH($D$1,CODE,0)),E2*INDEX(FPTS,MATCH($E$1,CODE,0)),F2*INDEX(FPTS,MATCH($F$1,CODE,0)),G2*INDEX(FPTS,MATCH($G$1,CODE,0)),H2*INDEX(FPTS,MATCH($H$1,CODE,0)),I2*INDEX(FPTS,MATCH($I$1,CODE,0)),J2*INDEX(FPTS,MATCH($J$1,CODE,0)),K2*INDEX(FPTS,MATCH($K$1,CODE,0)),L2*INDEX(FPTS,MATCH($L$1,CODE,0)),M2*INDEX(FPTS,MATCH($M$1,CODE,0)),N2*INDEX(FPTS,MATCH($N$1,CODE,0)),O2*INDEX(FPTS,MATCH($O$1,CODE,0)),P2*INDEX(FPTS,MATCH($P$1,CODE,0))) -> 0
A3: RB:BUF | N3: =IF(E3>=300,1,0) -> 0 | O3: =IF(F3>=100,1,0) -> 0 | P3: =IF(H3>=100,1,0) -> 0 | Q3: =SUM(B3*INDEX(GPTS,MATCH($B$1,CODE,0)),C3*INDEX(GPTS,MATCH($C$1,CODE,0)),D3*INDEX(GPTS,MATCH($D$1,CODE,0))) -> 0 | R3: =SUM(B3*INDEX(FPTS,MATCH($B$1,CODE,0)),C3*INDEX(FPTS,MATCH($C$1,CODE,0)),D3*INDEX(FPTS,MATCH($D$1,CODE,0)),E3*INDEX(FPTS,MATCH($E$1,CODE,0)),F3*INDEX(FPTS,MATCH($F$1,CODE,0)),G3*INDEX(FPTS,MATCH($G$1,CODE,0)),H3*INDEX(FPTS,MATCH($H$1,CODE,0)),I3*INDEX(FPTS,MATCH($I$1,CODE,0)),J3*INDEX(FPTS,MATCH($J$1,CODE,0)),K3*INDEX(FPTS,MATCH($K$1,CODE,0)),L3*INDEX(FPTS,MATCH($L$1,CODE,0)),M3*INDEX(FPTS,MATCH($M$1,CODE,0)),N3*INDEX(FPTS,MATCH($N$1,CODE,0)),O3*INDEX(FPTS,MATCH($O$1,CODE,0)),P3*INDEX(FPTS,MATCH($P$1,CODE,0))) -> 0
A4: TE:BUF | N4: =IF(E4>=300,1,0) -> 0 | O4: =IF(F4>=100,1,0) -> 0 | P4: =IF(H4>=100,1,0) -> 0 | Q4: =SUM(B4*INDEX(GPTS,MATCH($B$1,CODE,0)),C4*INDEX(GPTS,MATCH($C$1,CODE,0)),D4*INDEX(GPTS,MATCH($D$1,CODE,0))) -> 0 | R4: =SUM(B4*INDEX(FPTS,MATCH($B$1,CODE,0)),C4*INDEX(FPTS,MATCH($C$1,CODE,0)),D4*INDEX(FPTS,MATCH($D$1,CODE,0)),E4*INDEX(FPTS,MATCH($E$1,CODE,0)),F4*INDEX(FPTS,MATCH($F$1,CODE,0)),G4*INDEX(FPTS,MATCH($G$1,CODE,0)),H4*INDEX(FPTS,MATCH($H$1,CODE,0)),I4*INDEX(FPTS,MATCH($I$1,CODE,0)),J4*INDEX(FPTS,MATCH($J$1,CODE,0)),K4*INDEX(FPTS,MATCH($K$1,CODE,0)),L4*INDEX(FPTS,MATCH($L$1,CODE,0)),M4*INDEX(FPTS,MATCH($M$1,CODE,0)),N4*INDEX(FPTS,MATCH($N$1,CODE,0)),O4*INDEX(FPTS,MATCH($O$1,CODE,0)),P4*INDEX(FPTS,MATCH($P$1,CODE,0))) -> 0
A5: WR1:BUF | N5: =IF(E5>=300,1,0) -> 0 | O5: =IF(F5>=100,1,0) -> 0 | P5: =IF(H5>=100,1,0) -> 0 | Q5: =SUM(B5*INDEX(GPTS,MATCH($B$1,CODE,0)),C5*INDEX(GPTS,MATCH($C$1,CODE,0)),D5*INDEX(GPTS,MATCH($D$1,CODE,0))) -> 0 | R5: =SUM(B5*INDEX(FPTS,MATCH($B$1,CODE,0)),C5*INDEX(FPTS,MATCH($C$1,CODE,0)),D5*INDEX(FPTS,MATCH($D$1,CODE,0)),E5*INDEX(FPTS,MATCH($E$1,CODE,0)),F5*INDEX(FPTS,MATCH($F$1,CODE,0)),G5*INDEX(FPTS,MATCH($G$1,CODE,0)),H5*INDEX(FPTS,MATCH($H$1,CODE,0)),I5*INDEX(FPTS,MATCH($I$1,CODE,0)),J5*INDEX(FPTS,MATCH($J$1,CODE,0)),K5*INDEX(FPTS,MATCH($K$1,CODE,0)),L5*INDEX(FPTS,MATCH($L$1,CODE,0)),M5*INDEX(FPTS,MATCH($M$1,CODE,0)),N5*INDEX(FPTS,MATCH($N$1,CODE,0)),O5*INDEX(FPTS,MATCH($O$1,CODE,0)),P5*INDEX(FPTS,MATCH($P$1,CODE,0))) -> 0
A6: WR2:BUF | N6: =IF(E6>=300,1,0) -> 0 | O6: =IF(F6>=100,1,0) -> 0 | P6: =IF(H6>=100,1,0) -> 0 | Q6: =SUM(B6*INDEX(GPTS,MATCH($B$1,CODE,0)),C6*INDEX(GPTS,MATCH($C$1,CODE,0)),D6*INDEX(GPTS,MATCH($D$1,CODE,0))) -> 0 | R6: =SUM(B6*INDEX(FPTS,MATCH($B$1,CODE,0)),C6*INDEX(FPTS,MATCH($C$1,CODE,0)),D6*INDEX(FPTS,MATCH($D$1,CODE,0)),E6*INDEX(FPTS,MATCH($E$1,CODE,0)),F6*INDEX(FPTS,MATCH($F$1,CODE,0)),G6*INDEX(FPTS,MATCH($G$1,CODE,0)),H6*INDEX(FPTS,MATCH($H$1,CODE,0)),I6*INDEX(FPTS,MATCH($I$1,CODE,0)),J6*INDEX(FPTS,MATCH($J$1,CODE,0)),K6*INDEX(FPTS,MATCH($K$1,CODE,0)),L6*INDEX(FPTS,MATCH($L$1,CODE,0)),M6*INDEX(FPTS,MATCH($M$1,CODE,0)),N6*INDEX(FPTS,MATCH($N$1,CODE,0)),O6*INDEX(FPTS,MATCH($O$1,CODE,0)),P6*INDEX(FPTS,MATCH($P$1,CODE,0))) -> 0
A7: WR3:BUF | N7: =IF(E7>=300,1,0) -> 0 | O7: =IF(F7>=100,1,0) -> 0 | P7: =IF(H7>=100,1,0) -> 0 | Q7: =SUM(B7*INDEX(GPTS,MATCH($B$1,CODE,0)),C7*INDEX(GPTS,MATCH($C$1,CODE,0)),D7*INDEX(GPTS,MATCH($D$1,CODE,0))) -> 0 | R7: =SUM(B7*INDEX(FPTS,MATCH($B$1,CODE,0)),C7*INDEX(FPTS,MATCH($C$1,CODE,0)),D7*INDEX(FPTS,MATCH($D$1,CODE,0)),E7*INDEX(FPTS,MATCH($E$1,CODE,0)),F7*INDEX(FPTS,MATCH($F$1,CODE,0)),G7*INDEX(FPTS,MATCH($G$1,CODE,0)),H7*INDEX(FPTS,MATCH($H$1,CODE,0)),I7*INDEX(FPTS,MATCH($I$1,CODE,0)),J7*INDEX(FPTS,MATCH($J$1,CODE,0)),K7*INDEX(FPTS,MATCH($K$1,CODE,0)),L7*INDEX(FPTS,MATCH($L$1,CODE,0)),M7*INDEX(FPTS,MATCH($M$1,CODE,0)),N7*INDEX(FPTS,MATCH($N$1,CODE,0)),O7*INDEX(FPTS,MATCH($O$1,CODE,0)),P7*INDEX(FPTS,MATCH($P$1,CODE,0))) -> 0
A9: D | B9: DE/RTD | C9: DE/SF | D9: DE/XPR | E9: FR | F9: DE/I | G9: S | H9: DE/B | I9: DE/PA0 | J9: DE/PA1-6 | K9: DE/PA7-13 | L9: DE/PA14-20 | M9: DE/PA28-34 | N9: DE/PA35+
A10: D:BUF | I10: =IF('BAL - Projections'!Q15=0,1,0) -> 1 | J10: =IF(AND('BAL - Projections'!Q15>0,'BAL - Projections'!Q15<7),1,0) -> 0 | K10: =IF(AND('BAL - Projections'!Q15>6,'BAL - Projections'!Q15<14),1,0) -> 0 | L10: =IF(AND('BAL - Projections'!Q15>13,'BAL - Projections'!Q15<21),1,0) -> 0 | M10: =IF(AND('BAL - Projections'!Q15>27,'BAL - Projections'!Q15<35),1,0) -> 0 | N10: =IF('BAL - Projections'!Q15>35,1,0) -> 0 | Q10: =SUM(B10*INDEX(GPTS,MATCH($B$9,CODE,0)),C10*INDEX(GPTS,MATCH($C$9,CODE,0)),D10*INDEX(GPTS,MATCH($D$9,CODE,0))) -> 0 | R10: =SUM(B10*INDEX(FPTS,MATCH($B$9,CODE,0)),C10*INDEX(FPTS,MATCH($C$9,CODE,0)),D10*INDEX(FPTS,MATCH($D$9,CODE,0)),E10*INDEX(FPTS,MATCH($E$9,CODE,0)),F10*INDEX(FPTS,MATCH($F$9,CODE,0)),G10*INDEX(FPTS,MATCH($G$9,CODE,0)),H10*INDEX(FPTS,MATCH($H$9,CODE,0)),I10*INDEX(FPTS,MATCH($I$9,CODE,0)),J10*INDEX(FPTS,MATCH($J$9,CODE,0)),K10*INDEX(FPTS,MATCH($K$9,CODE,0)),L10*INDEX(FPTS,MATCH($L$9,CODE,0)),M10*INDEX(FPTS,MATCH($M$9,CODE,0)),N10*INDEX(FPTS,MATCH($N$9,CODE,0))) -> 10
A12: K | B12: FGu20 | C12: FGu30 | D12: FGu40 | E12: FGu50 | F12: FGo50 | G12: XP | H12: 2PC/S | I12: 2PC/P | J12: FU/L
A13: K:BUF | Q13: =SUM(B13*INDEX(GPTS,MATCH($B$12,CODE,0)),C13*INDEX(GPTS,MATCH($C$12,CODE,0)),D13*INDEX(GPTS,MATCH($D$12,CODE,0)),E13*INDEX(GPTS,MATCH($E$12,CODE,0)),F13*INDEX(GPTS,MATCH($F$12,CODE,0)),G13*INDEX(GPTS,MATCH($G$12,CODE,0)),H13*INDEX(GPTS,MATCH($H$12,CODE,0)),I13*INDEX(GPTS,MATCH($I$12,CODE,0)),J13*INDEX(GPTS,MATCH($J$12,CODE,0))) -> 0 | R13: =SUM(B13*INDEX(FPTS,MATCH($B$12,CODE,0)),C13*INDEX(FPTS,MATCH($C$12,CODE,0)),D13*INDEX(FPTS,MATCH($D$12,CODE,0)),E13*INDEX(FPTS,MATCH($E$12,CODE,0)),F13*INDEX(FPTS,MATCH($F$12,CODE,0)),G13*INDEX(FPTS,MATCH($G$12,CODE,0)),H13*INDEX(FPTS,MATCH($H$12,CODE,0)),I13*INDEX(FPTS,MATCH($I$12,CODE,0)),J13*INDEX(FPTS,MATCH($J$12,CODE,0))) -> 0
A15: TOTALS | Q15: =SUM(Q1:Q13) -> 0 | R15: =SUM(R1:R13) -> 10

Sheet Point Matrix
A1: CODE | B1: FPTS | C1: GPTS | D1: DESCRIPTION
A2: DE/SF | B2: 2 | C2: 2 | D2: Safeties
A3: DE/RTD | B3: 6 | C3: 6 | D3: Return TDs
A4: DE/FRTD | B4: 6 | C4: 6 | D4: Fumble Return TDs
A5: DE/BRTD | B5: 6 | C5: 6 | D5: Blocked Kick Return TDs
A6: DE/XPR | B6: 2 | C6: 2 | D6: Extra Point Return
A7: DE/PA0 | B7: 10 | D7: 0 Points Allowed
A8: DE/PA1-6 | B8: 7 | D8: 1-6 Points Allowed
A9: DE/PA7-13 | B9: 4 | D9: 7-13 Points Allowed
A10: DE/PA14-20 | B10: 1 | D10: 14-20 Points Allowed
A11: DE/PA28-34 | B11: -1 | D11: 28-34 Points Allowed
A12: DE/PA35+ | B12: -4 | D12: 35+ Points Allowed
A13: DE/I | B13: 2 | D13: Interceptions
A14: S | B14: 1 | D14: Sacks
A15: DE/B | B15: 2 | D15: Blocked Punts/Kicks
A16: FGu20 | B16: 3 | C16: 3 | D16: 0-19 Yards
A17: FGu30 | B17: 3 | C17: 3 | D17: 20-29 Yards
A18: FGu40 | B18: 3 | C18: 3 | D18: 30-39 Yards
A19: FGu50 | B19: 4 | C19: 3 | D19: 40-49 Yards
A20: FGo50 | B20: 5 | C20: 3 | D20: 50+ Yards
A21: XP | B21: 1 | C21: 1 | D21: Extra-point Conversions
A22: RuTD | B22: 6 | C22: 6 | D22: Rushing TDs
A23: ReTD | B23: 6 | C23: 6 | D23: Receiving TDs
A24: FU/TD | B24: 6 | C24: 6 | D24: Own Fumbles Recovered TDs
A25: KR/TD | B25: 6 | C25: 6 | D25: Kickoff Return TDs
A26: PR/TD | B26: 6 | C26: 6 | D26: Punt Return TDs
A27: 2PC/S | B27: 2 | C27: 2 | D27: Two-point Conversion Scored
A28: PaY | B28: 0.04 | D28: Passing Yards
A29: PaTD | B29: 4 | D29: Passing TDs
A30: 300+ PaY Gm | B30: 3 | D30: 300+ Passing Yards
A31: I | B31: -1 | D31: Interceptions
A32: RuY | B32: 0.1 | D32: Rushing Yds
A33: 100+ RuY GM | B33: 3 | D33: 100+ Rushing Yards
A34: Re | B34: 0.5 | D34: Receptions
A35: ReY | B35: 0.1 | D35: Receiving Yards
A36: 100+ ReY GM | B36: 3 | D36: 100+ Receiving Yds
A37: 2PC/P | B37: 2 | D37: Two-point Conversion Passes
A38: FR | B38: 2 | D38: Fumbles Recovered
A39: FU/L | B39: -2 | D39: Fumbles Lost
A40: TD | B40: 6 | C40: 6 | D40: Touch Down
...

Sheet Headers
B1: QB:DAL | C1: RB:DAL | D1: TE:DAL | E1: WR1:DAL | F1: WR2:DAL | G1: WR3:DAL | I1: K:DAL | K1: D:DAL | N1: QB:PHI | O1: RB:PHI | P1: TE:PHI | Q1: WR1:PHI | R1: WR2:PHI | S1: WR3:PHI | V1: K:PHI | Y1: D:PHI
A2: TD | H2: FGu20 | J2: DE/SF | M2: TD | U2: FGu20 | X2: DE/SF
A3: 2PC/S | H3: FGu30 | J3: DE/XPR | M3: 2PC/S | U3: FGu30 | X3: DE/XPR
A4: PaTD | H4: FGu40 | J4: FR | M4: PaTD | U4: FGu40 | X4: FR
A5: PaY | H5: FGu50 | J5: FU/L | M5: PaY | U5: FGu50 | X5: FU/L
A6: 300+ PaY Gm | H6: FGo50 | J6: DE/PA0 | M6: 300+ PaY Gm | U6: FGo50 | X6: DE/PA0
A7: I | H7: XP | J7: DE/PA1-6 | M7: I | U7: XP | X7: DE/PA1-6
A8: RuY | J8: DE/PA7-13 | M8: RuY | X8: DE/PA7-13
A9: 100+ RuY GM | J9: DE/PA14-20 | M9: 100+ RuY GM | X9: DE/PA14-20
A10: Re | J10: DE/PA28-34 | M10: Re | X10: DE/PA28-34
A11: ReY | J11: DE/PA35+ | M11: ReY | X11: DE/PA35+
A12: 100+ ReY GM | J12: DE/I | M12: 100+ ReY GM | X12: DE/I
A13: 2PC/P | J13: S | M13: 2PC/P | X13: S
J14: DE/B | X14: DE/B
