Workbook
Name key: Retro!$K$1:INDEX(Retro!$K:$K,COUNTA(Retro!$K:$K))
Name key_team_cnt: Retro!$K$1:$R$46
Name MVP_pos: Retro!$L$1:INDEX(Retro!$L:$L,COUNTA(Retro!$L:$L))
Name MVPbyPlayer: 'MVP by Player'!$U$2:INDEX(!$R:$R,COUNTA('MVP by Player'!$R:$R))
Name retro: Retro!$I$1:INDEX(Retro!$AB:$AB,COUNTA(Retro!$AB:$AB))
Name team_cnt: Retro!$R$1:INDEX(Retro!$R:$R,COUNTA(Retro!$R:$R))
Name WinsByPosition: 'Position Matrix'!$A$77:$D$86

Sheet Wins by Key
B24: Key | C24: Wins | D24: Wins + MVP | E24: Games | F24: Wins% | G24: MVP% | L24: {=[1]!sql(SQL!B3,retro)} -> sqlite3.OperationalError: no such column: key ~~~~~~~~~^^^^^^^ c.execute(query) File "C:\Users\mxmei\anaconda3\Lib\site-packages\xlwings\ext\sql.py", line 68, in _sql return _sql(query, *tables) File "C:\Users\mxmei\anaconda3\Lib\site-packages\xlwings\ext\sql.py", line 28, in sql_dynamic ret = func(*args) File "C:\Users\mxmei\anaconda3\Lib\site-packages\xlwings\udfs.py", line 536, in call_udf res = call_udf(script, fname, args, this_workbook, FromVariant(caller)) File "C:\Users\mxmei\anaconda3\Lib\site-packages\xlwings\com_server.py", line 235, in CallUDF return func(*args) File "C:\Users\mxmei\anaconda3\Lib\site-packages\win32com\server\policy.py", line 633, in _invokeex_ ~~~~~~~~~~~~~~~^^^^^^^^^^^^^^^^^^^^^^^^^^^^^^^^^^^^^^^^ return S_OK, -1, self._invokeex_(dispid, lcid, wFlags, args, None, None) File "C:\Users\mxmei\anaconda3\Lib\site-packages\win32com\server\policy.py", line 303, in _invoke_ ~~~~~~~~~~~~~^^^^^^^^^^^^^^^^^^^^^^^^^^^^ return self._invoke_(dispid, lcid, wFlags, args) File "C:\Users\mxmei\anaconda3\Lib\site-packages\win32com\server\policy.py", line 298, in _Invoke_ | M24: sqlite3.OperationalError: no such column: key ~~~~~~~~~^^^^^^^ c.execute(query) File "C:\Users\mxmei\anaconda3\Lib\site-packages\xlwings\ext\sql.py", line 68, in _sql return _sql(query, *tables) File "C:\Users\mxmei\anaconda3\Lib\site-packages\xlwings\ext\sql.py", line 28, in sql_dynamic ret = func(*args) File "C:\Users\mxmei\anaconda3\Lib\site-packages\xlwings\udfs.py", line 536, in call_udf res = call_udf(script, fname, args, this_workbook, FromVariant(caller)) File "C:\Users\mxmei\anaconda3\Lib\site-packages\xlwings\com_server.py", line 235, in CallUDF return func(*args) File "C:\Users\mxmei\anaconda3\Lib\site-packages\win32com\server\policy.py", line 633, in _invokeex_ ~~~~~~~~~~~~~~~^^^^^^^^^^^^^^^^^^^^^^^^^^^^^^^^^^^^^^^^ return S_OK, -1, self._invokeex_(dispid, lcid, wFlags, args, None, None) File "C:\Users\mxmei\anaconda3\Lib\site-packages\win32com\server\policy.py", line 303, in _invoke_ ~~~~~~~~~~~~~^^^^^^^^^^^^^^^^^^^^^^^^^^^^ return self._invoke_(dispid, lcid, wFlags, args) File "C:\Users\mxmei\anaconda3\Lib\site-packages\win32com\server\policy.py", line 298, in _Invoke_ | N24: sqlite3.OperationalError: no such column: key ~~~~~~~~~^^^^^^^ c.execute(query) File "C:\Users\mxmei\anaconda3\Lib\site-packages\xlwings\ext\sql.py", line 68, in _sql return _sql(query, *tables) File "C:\Users\mxmei\anaconda3\Lib\site-packages\xlwings\ext\sql.py", line 28, in sql_dynamic ret = func(*args) File "C:\Users\mxmei\anaconda3\Lib\site-packages\xlwings\udfs.py", line 536, in call_udf res = call_udf(script, fname, args, this_workbook, FromVariant(caller)) File "C:\Users\mxmei\anaconda3\Lib\site-packages\xlwings\com_server.py", line 235, in CallUDF return func(*args) File "C:\Users\mxmei\anaconda3\Lib\site-packages\win32com\server\policy.py", line 633, in _invokeex_ ~~~~~~~~~~~~~~~^^^^^^^^^^^^^^^^^^^^^^^^^^^^^^^^^^^^^^^^ return S_OK, -1, self._invokeex_(dispid, lcid, wFlags, args, None, None) File "C:\Users\mxmei\anaconda3\Lib\site-packages\win32com\server\policy.py", line 303, in _invoke_ ~~~~~~~~~~~~~^^^^^^^^^^^^^^^^^^^^^^^^^^^^ return self._invoke_(dispid, lcid, wFlags, args) File "C:\Users\mxmei\anaconda3\Lib\site-packages\win32com\server\policy.py", line 298, in _Invoke_ | P24: Games | Q24: Picks
B25: 1 | C25: =COUNTIFS(Retro!$K$2:$K$72,">=10",Retro!$K$2:$K$72,"<=19") -> 22 | D25: =COUNTIFS(Retro!$K$2:$K$72,">=10",Retro!$K$2:$K$72,"<=19",Retro!$L$2:$L$72,1) -> 11 | E25: =COUNT(Retro!$K$2:$K$72) -> 71 | F25: =C25/E25 -> 0.30985915 | G25: =D25/E25 -> 0.15492958 | L25: sqlite3.OperationalError: no such column: key ~~~~~~~~~^^^^^^^ c.execute(query) File "C:\Users\mxmei\anaconda3\Lib\site-packages\xlwings\ext\sql.py", line 68, in _sql return _sql(query, *tables) File "C:\Users\mxmei\anaconda3\Lib\site-packages\xlwings\ext\sql.py", line 28, in sql_dynamic ret = func(*args) File "C:\Users\mxmei\anaconda3\Lib\site-packages\xlwings\udfs.py", line 536, in call_udf res = call_udf(script, fname, args, this_workbook, FromVariant(caller)) File "C:\Users\mxmei\anaconda3\Lib\site-packages\xlwings\com_server.py", line 235, in CallUDF return func(*args) File "C:\Users\mxmei\anaconda3\Lib\site-packages\win32com\server\policy.py", line 633, in _invokeex_ ~~~~~~~~~~~~~~~^^^^^^^^^^^^^^^^^^^^^^^^^^^^^^^^^^^^^^^^ return S_OK, -1, self._invokeex_(dispid, lcid, wFlags, args, None, None) File "C:\Users\mxmei\anaconda3\Lib\site-packages\win32com\server\policy.py", line 303, in _invoke_ ~~~~~~~~~~~~~^^^^^^^^^^^^^^^^^^^^^^^^^^^^ return self._invoke_(dispid, lcid, wFlags, args) File "C:\Users\mxmei\anaconda3\Lib\site-packages\win32com\server\policy.py", line 298, in _Invoke_ | M25: sqlite3.OperationalError: no such column: key ~~~~~~~~~^^^^^^^ c.execute(query) File "C:\Users\mxmei\anaconda3\Lib\site-packages\xlwings\ext\sql.py", line 68, in _sql return _sql(query, *tables) File "C:\Users\mxmei\anaconda3\Lib\site-packages\xlwings\ext\sql.py", line 28, in sql_dynamic ret = func(*args) File "C:\Users\mxmei\anaconda3\Lib\site-packages\xlwings\udfs.py", line 536, in call_udf res = call_udf(script, fname, args, this_workbook, FromVariant(caller)) File "C:\Users\mxmei\anaconda3\Lib\site-packages\xlwings\com_server.py", line 235, in CallUDF return func(*args) File "C:\Users\mxmei\anaconda3\Lib\site-packages\win32com\server\policy.py", line 633, in _invokeex_ ~~~~~~~~~~~~~~~^^^^^^^^^^^^^^^^^^^^^^^^^^^^^^^^^^^^^^^^ return S_OK, -1, self._invokeex_(dispid, lcid, wFlags, args, None, None) File "C:\Users\mxmei\anaconda3\Lib\site-packages\win32com\server\policy.py", line 303, in _invoke_ ~~~~~~~~~~~~~^^^^^^^^^^^^^^^^^^^^^^^^^^^^ return self._invoke_(dispid, lcid, wFlags, args) File "C:\Users\mxmei\anaconda3\Lib\site-packages\win32com\server\policy.py", line 298, in _Invoke_ | N25: sqlite3.OperationalError: no such column: key ~~~~~~~~~^^^^^^^ c.execute(query) File "C:\Users\mxmei\anaconda3\Lib\site-packages\xlwings\ext\sql.py", line 68, in _sql return _sql(query, *tables) File "C:\Users\mxmei\anaconda3\Lib\site-packages\xlwings\ext\sql.py", line 28, in sql_dynamic ret = func(*args) File "C:\Users\mxmei\anaconda3\Lib\site-packages\xlwings\udfs.py", line 536, in call_udf res = call_udf(script, fname, args, this_workbook, FromVariant(caller)) File "C:\Users\mxmei\anaconda3\Lib\site-packages\xlwings\com_server.py", line 235, in CallUDF return func(*args) File "C:\Users\mxmei\anaconda3\Lib\site-packages\win32com\server\policy.py", line 633, in _invokeex_ ~~~~~~~~~~~~~~~^^^^^^^^^^^^^^^^^^^^^^^^^^^^^^^^^^^^^^^^ return S_OK, -1, self._invokeex_(dispid, lcid, wFlags, args, None, None) File "C:\Users\mxmei\anaconda3\Lib\site-packages\win32com\server\policy.py", line 303, in _invoke_ ~~~~~~~~~~~~~^^^^^^^^^^^^^^^^^^^^^^^^^^^^ return self._invoke_(dispid, lcid, wFlags, args) File "C:\Users\mxmei\anaconda3\Lib\site-packages\win32com\server\policy.py", line 298, in _Invoke_ | P25: 10 | Q25: =$P$25*N25 -> #VALUE! | R25: 4
B26: 2 | C26: =COUNTIFS(Retro!$K$2:$K$72,">=20",Retro!$K$2:$K$72,"<=29") -> 10 | D26: =COUNTIFS(Retro!$K$2:$K$72,">=20",Retro!$K$2:$K$72,"<=29",Retro!$L$2:$L$72,2) -> 6 | E26: =COUNT(Retro!$K$2:$K$72) -> 71 | F26: =C26/E26 -> 0.14084507 | G26: =D26/E26 -> 0.084507042 | L26: sqlite3.OperationalError: no such column: key ~~~~~~~~~^^^^^^^ c.execute(query) File "C:\Users\mxmei\anaconda3\Lib\site-packages\xlwings\ext\sql.py", line 68, in _sql return _sql(query, *tables) File "C:\Users\mxmei\anaconda3\Lib\site-packages\xlwings\ext\sql.py", line 28, in sql_dynamic ret = func(*args) File "C:\Users\mxmei\anaconda3\Lib\site-packages\xlwings\udfs.py", line 536, in call_udf res = call_udf(script, fname, args, this_workbook, FromVariant(caller)) File "C:\Users\mxmei\anaconda3\Lib\site-packages\xlwings\com_server.py", line 235, in CallUDF return func(*args) File "C:\Users\mxmei\anaconda3\Lib\site-packages\win32com\server\policy.py", line 633, in _invokeex_ ~~~~~~~~~~~~~~~^^^^^^^^^^^^^^^^^^^^^^^^^^^^^^^^^^^^^^^^ return S_OK, -1, self._invokeex_(dispid, lcid, wFlags, args, None, None) File "C:\Users\mxmei\anaconda3\Lib\site-packages\win32com\server\policy.py", line 303, in _invoke_ ~~~~~~~~~~~~~^^^^^^^^^^^^^^^^^^^^^^^^^^^^ return self._invoke_(dispid, lcid, wFlags, args) File "C:\Users\mxmei\anaconda3\Lib\site-packages\win32com\server\policy.py", line 298, in _Invoke_ | M26: sqlite3.OperationalError: no such column: key ~~~~~~~~~^^^^^^^ c.execute(query) File "C:\Users\mxmei\anaconda3\Lib\site-packages\xlwings\ext\sql.py", line 68, in _sql return _sql(query, *tables) File "C:\Users\mxmei\anaconda3\Lib\site-packages\xlwings\ext\sql.py", line 28, in sql_dynamic ret = func(*args) File "C:\Users\mxmei\anaconda3\Lib\site-packages\xlwings\udfs.py", line 536, in call_udf res = call_udf(script, fname, args, this_workbook, FromVariant(caller)) File "C:\Users\mxmei\anaconda3\Lib\site-packages\xlwings\com_server.py", line 235, in CallUDF return func(*args) File "C:\Users\mxmei\anaconda3\Lib\site-packages\win32com\server\policy.py", line 633, in _invokeex_ ~~~~~~~~~~~~~~~^^^^^^^^^^^^^^^^^^^^^^^^^^^^^^^^^^^^^^^^ return S_OK, -1, self._invokeex_(dispid, lcid, wFlags, args, None, None) File "C:\Users\mxmei\anaconda3\Lib\site-packages\win32com\server\policy.py", line 303, in _invoke_ ~~~~~~~~~~~~~^^^^^^^^^^^^^^^^^^^^^^^^^^^^ return self._invoke_(dispid, lcid, wFlags, args) File "C:\Users\mxmei\anaconda3\Lib\site-packages\win32com\server\policy.py", line 298, in _Invoke_ | N26: sqlite3.OperationalError: no such column: key ~~~~~~~~~^^^^^^^ c.execute(query) File "C:\Users\mxmei\anaconda3\Lib\site-packages\xlwings\ext\sql.py", line 68, in _sql return _sql(query, *tables) File "C:\Users\mxmei\anaconda3\Lib\site-packages\xlwings\ext\sql.py", line 28, in sql_dynamic ret = func(*args) File "C:\Users\mxmei\anaconda3\Lib\site-packages\xlwings\udfs.py", line 536, in call_udf res = call_udf(script, fname, args, this_workbook, FromVariant(caller)) File "C:\Users\mxmei\anaconda3\Lib\site-packages\xlwings\com_server.py", line 235, in CallUDF return func(*args) File "C:\Users\mxmei\anaconda3\Lib\site-packages\win32com\server\policy.py", line 633, in _invokeex_ ~~~~~~~~~~~~~~~^^^^^^^^^^^^^^^^^^^^^^^^^^^^^^^^^^^^^^^^ return S_OK, -1, self._invokeex_(dispid, lcid, wFlags, args, None, None) File "C:\Users\mxmei\anaconda3\Lib\site-packages\win32com\server\policy.py", line 303, in _invoke_ ~~~~~~~~~~~~~^^^^^^^^^^^^^^^^^^^^^^^^^^^^ return self._invoke_(dispid, lcid, wFlags, args) File "C:\Users\mxmei\anaconda3\Lib\site-packages\win32com\server\policy.py", line 298, in _Invoke_ | Q26: =$P$25*N26 -> #VALUE! | R26: 3
B27: 3 | C27: =COUNTIFS(Retro!$K$2:$K$72,">=30",Retro!$K$2:$K$72,"<=39") -> 4 | D27: =COUNTIFS(Retro!$K$2:$K$72,">=30",Retro!$K$2:$K$72,"<=39",Retro!$L$2:$L$72,3) -> 1 | E27: =COUNT(Retro!$K$2:$K$72) -> 71 | F27: =C27/E27 -> 0.056338028 | G27: =D27/E27 -> 0.014084507 | L27: sqlite3.OperationalError: no such column: key ~~~~~~~~~^^^^^^^ c.execute(query) File "C:\Users\mxmei\anaconda3\Lib\site-packages\xlwings\ext\sql.py", line 68, in _sql return _sql(query, *tables) File "C:\Users\mxmei\anaconda3\Lib\site-packages\xlwings\ext\sql.py", line 28, in sql_dynamic ret = func(*args) File "C:\Users\mxmei\anaconda3\Lib\site-packages\xlwings\udfs.py", line 536, in call_udf res = call_udf(script, fname, args, this_workbook, FromVariant(caller)) File "C:\Users\mxmei\anaconda3\Lib\site-packages\xlwings\com_server.py", line 235, in CallUDF return func(*args) File "C:\Users\mxmei\anaconda3\Lib\site-packages\win32com\server\policy.py", line 633, in _invokeex_ ~~~~~~~~~~~~~~~^^^^^^^^^^^^^^^^^^^^^^^^^^^^^^^^^^^^^^^^ return S_OK, -1, self._invokeex_(dispid, lcid, wFlags, args, None, None) File "C:\Users\mxmei\anaconda3\Lib\site-packages\win32com\server\policy.py", line 303, in _invoke_ ~~~~~~~~~~~~~^^^^^^^^^^^^^^^^^^^^^^^^^^^^ return self._invoke_(dispid, lcid, wFlags, args) File "C:\Users\mxmei\anaconda3\Lib\site-packages\win32com\server\policy.py", line 298, in _Invoke_ | M27: sqlite3.OperationalError: no such column: key ~~~~~~~~~^^^^^^^ c.execute(query) File "C:\Users\mxmei\anaconda3\Lib\site-packages\xlwings\ext\sql.py", line 68, in _sql return _sql(query, *tables) File "C:\Users\mxmei\anaconda3\Lib\site-packages\xlwings\ext\sql.py", line 28, in sql_dynamic ret = func(*args) File "C:\Users\mxmei\anaconda3\Lib\site-packages\xlwings\udfs.py", line 536, in call_udf res = call_udf(script, fname, args, this_workbook, FromVariant(caller)) File "C:\Users\mxmei\anaconda3\Lib\site-packages\xlwings\com_server.py", line 235, in CallUDF return func(*args) File "C:\Users\mxmei\anaconda3\Lib\site-packages\win32com\server\policy.py", line 633, in _invokeex_ ~~~~~~~~~~~~~~~^^^^^^^^^^^^^^^^^^^^^^^^^^^^^^^^^^^^^^^^ return S_OK, -1, self._invokeex_(dispid, lcid, wFlags, args, None, None) File "C:\Users\mxmei\anaconda3\Lib\site-packages\win32com\server\policy.py", line 303, in _invoke_ ~~~~~~~~~~~~~^^^^^^^^^^^^^^^^^^^^^^^^^^^^ return self._invoke_(dispid, lcid, wFlags, args) File "C:\Users\mxmei\anaconda3\Lib\site-packages\win32com\server\policy.py", line 298, in _Invoke_ | N27: sqlite3.OperationalError: no such column: key ~~~~~~~~~^^^^^^^ c.execute(query) File "C:\Users\mxmei\anaconda3\Lib\site-packages\xlwings\ext\sql.py", line 68, in _sql return _sql(query, *tables) File "C:\Users\mxmei\anaconda3\Lib\site-packages\xlwings\ext\sql.py", line 28, in sql_dynamic ret = func(*args) File "C:\Users\mxmei\anaconda3\Lib\site-packages\xlwings\udfs.py", line 536, in call_udf res = call_udf(script, fname, args, this_workbook, FromVariant(caller)) File "C:\Users\mxmei\anaconda3\Lib\site-packages\xlwings\com_server.py", line 235, in CallUDF return func(*args) File "C:\Users\mxmei\anaconda3\Lib\site-packages\win32com\server\policy.py", line 633, in _invokeex_ ~~~~~~~~~~~~~~~^^^^^^^^^^^^^^^^^^^^^^^^^^^^^^^^^^^^^^^^ return S_OK, -1, self._invokeex_(dispid, lcid, wFlags, args, None, None) File "C:\Users\mxmei\anaconda3\Lib\site-packages\win32com\server\policy.py", line 303, in _invoke_ ~~~~~~~~~~~~~^^^^^^^^^^^^^^^^^^^^^^^^^^^^ return self._invoke_(dispid, lcid, wFlags, args) File "C:\Users\mxmei\anaconda3\Lib\site-packages\win32com\server\policy.py", line 298, in _Invoke_ | Q27: =$P$25*N27 -> #VALUE! | R27: 2
B28: 4 | C28: =COUNTIFS(Retro!$K$2:$K$72,">=40",Retro!$K$2:$K$72,"<=49") -> 0 | D28: =COUNTIFS(Retro!$K$2:$K$72,">=40",Retro!$K$2:$K$72,"<=49",Retro!$L$2:$L$72,4) -> 0 | E28: =COUNT(Retro!$K$2:$K$72) -> 71 | F28: =C28/E28 -> 0 | G28: =D28/E28 -> 0 | L28: sqlite3.OperationalError: no such column: key ~~~~~~~~~^^^^^^^ c.execute(query) File "C:\Users\mxmei\anaconda3\Lib\site-packages\xlwings\ext\sql.py", line 68, in _sql return _sql(query, *tables) File "C:\Users\mxmei\anaconda3\Lib\site-packages\xlwings\ext\sql.py", line 28, in sql_dynamic ret = func(*args) File "C:\Users\mxmei\anaconda3\Lib\site-packages\xlwings\udfs.py", line 536, in call_udf res = call_udf(script, fname, args, this_workbook, FromVariant(caller)) File "C:\Users\mxmei\anaconda3\Lib\site-packages\xlwings\com_server.py", line 235, in CallUDF return func(*args) File "C:\Users\mxmei\anaconda3\Lib\site-packages\win32com\server\policy.py", line 633, in _invokeex_ ~~~~~~~~~~~~~~~^^^^^^^^^^^^^^^^^^^^^^^^^^^^^^^^^^^^^^^^ return S_OK, -1, self._invokeex_(dispid, lcid, wFlags, args, None, None) File "C:\Users\mxmei\anaconda3\Lib\site-packages\win32com\server\policy.py", line 303, in _invoke_ ~~~~~~~~~~~~~^^^^^^^^^^^^^^^^^^^^^^^^^^^^ return self._invoke_(dispid, lcid, wFlags, args) File "C:\Users\mxmei\anaconda3\Lib\site-packages\win32com\server\policy.py", line 298, in _Invoke_ | M28: sqlite3.OperationalError: no such column: key ~~~~~~~~~^^^^^^^ c.execute(query) File "C:\Users\mxmei\anaconda3\Lib\site-packages\xlwings\ext\sql.py", line 68, in _sql return _sql(query, *tables) File "C:\Users\mxmei\anaconda3\Lib\site-packages\xlwings\ext\sql.py", line 28, in sql_dynamic ret = func(*args) File "C:\Users\mxmei\anaconda3\Lib\site-packages\xlwings\udfs.py", line 536, in call_udf res = call_udf(script, fname, args, this_workbook, FromVariant(caller)) File "C:\Users\mxmei\anaconda3\Lib\site-packages\xlwings\com_server.py", line 235, in CallUDF return func(*args) File "C:\Users\mxmei\anaconda3\Lib\site-packages\win32com\server\policy.py", line 633, in _invokeex_ ~~~~~~~~~~~~~~~^^^^^^^^^^^^^^^^^^^^^^^^^^^^^^^^^^^^^^^^ return S_OK, -1, self._invokeex_(dispid, lcid, wFlags, args, None, None) File "C:\Users\mxmei\anaconda3\Lib\site-packages\win32com\server\policy.py", line 303, in _invoke_ ~~~~~~~~~~~~~^^^^^^^^^^^^^^^^^^^^^^^^^^^^ return self._invoke_(dispid, lcid, wFlags, args) File "C:\Users\mxmei\anaconda3\Lib\site-packages\win32com\server\policy.py", line 298, in _Invoke_ | N28: sqlite3.OperationalError: no such column: key ~~~~~~~~~^^^^^^^ c.execute(query) File "C:\Users\mxmei\anaconda3\Lib\site-packages\xlwings\ext\sql.py", line 68, in _sql return _sql(query, *tables) File "C:\Users\mxmei\anaconda3\Lib\site-packages\xlwings\ext\sql.py", line 28, in sql_dynamic ret = func(*args) File "C:\Users\mxmei\anaconda3\Lib\site-packages\xlwings\udfs.py", line 536, in call_udf res = call_udf(script, fname, args, this_workbook, FromVariant(caller)) File "C:\Users\mxmei\anaconda3\Lib\site-packages\xlwings\com_server.py", line 235, in CallUDF return func(*args) File "C:\Users\mxmei\anaconda3\Lib\site-packages\win32com\server\policy.py", line 633, in _invokeex_ ~~~~~~~~~~~~~~~^^^^^^^^^^^^^^^^^^^^^^^^^^^^^^^^^^^^^^^^ return S_OK, -1, self._invokeex_(dispid, lcid, wFlags, args, None, None) File "C:\Users\mxmei\anaconda3\Lib\site-packages\win32com\server\policy.py", line 303, in _invoke_ ~~~~~~~~~~~~~^^^^^^^^^^^^^^^^^^^^^^^^^^^^ return self._invoke_(dispid, lcid, wFlags, args) File "C:\Users\mxmei\anaconda3\Lib\site-packages\win32com\server\policy.py", line 298, in _Invoke_ | Q28: =$P$25*N28 -> #VALUE! | R28: 1
C29: =SUM(C25:C28) -> 36 | D29: =SUM(D25:D28) -> 18 | L29: sqlite3.OperationalError: no such column: key ~~~~~~~~~^^^^^^^ c.execute(query) File "C:\Users\mxmei\anaconda3\Lib\site-packages\xlwings\ext\sql.py", line 68, in _sql return _sql(query, *tables) File "C:\Users\mxmei\anaconda3\Lib\site-packages\xlwings\ext\sql.py", line 28, in sql_dynamic ret = func(*args) File "C:\Users\mxmei\anaconda3\Lib\site-packages\xlwings\udfs.py", line 536, in call_udf res = call_udf(script, fname, args, this_workbook, FromVariant(caller)) File "C:\Users\mxmei\anaconda3\Lib\site-packages\xlwings\com_server.py", line 235, in CallUDF return func(*args) File "C:\Users\mxmei\anaconda3\Lib\site-packages\win32com\server\policy.py", line 633, in _invokeex_ ~~~~~~~~~~~~~~~^^^^^^^^^^^^^^^^^^^^^^^^^^^^^^^^^^^^^^^^ return S_OK, -1, self._invokeex_(dispid, lcid, wFlags, args, None, None) File "C:\Users\mxmei\anaconda3\Lib\site-packages\win32com\server\policy.py", line 303, in _invoke_ ~~~~~~~~~~~~~^^^^^^^^^^^^^^^^^^^^^^^^^^^^ return self._invoke_(dispid, lcid, wFlags, args) File "C:\Users\mxmei\anaconda3\Lib\site-packages\win32com\server\policy.py", line 298, in _Invoke_ | M29: sqlite3.OperationalError: no such column: key ~~~~~~~~~^^^^^^^ c.execute(query) File "C:\Users\mxmei\anaconda3\Lib\site-packages\xlwings\ext\sql.py", line 68, in _sql return _sql(query, *tables) File "C:\Users\mxmei\anaconda3\Lib\site-packages\xlwings\ext\sql.py", line 28, in sql_dynamic ret = func(*args) File "C:\Users\mxmei\anaconda3\Lib\site-packages\xlwings\udfs.py", line 536, in call_udf res = call_udf(script, fname, args, this_workbook, FromVariant(caller)) File "C:\Users\mxmei\anaconda3\Lib\site-packages\xlwings\com_server.py", line 235, in CallUDF return func(*args) File "C:\Users\mxmei\anaconda3\Lib\site-packages\win32com\server\policy.py", line 633, in _invokeex_ ~~~~~~~~~~~~~~~^^^^^^^^^^^^^^^^^^^^^^^^^^^^^^^^^^^^^^^^ return S_OK, -1, self._invokeex_(dispid, lcid, wFlags, args, None, None) File "C:\Users\mxmei\anaconda3\Lib\site-packages\win32com\server\policy.py", line 303, in _invoke_ ~~~~~~~~~~~~~^^^^^^^^^^^^^^^^^^^^^^^^^^^^ return self._invoke_(dispid, lcid, wFlags, args) File "C:\Users\mxmei\anaconda3\Lib\site-packages\win32com\server\policy.py", line 298, in _Invoke_ | N29: sqlite3.OperationalError: no such column: key ~~~~~~~~~^^^^^^^ c.execute(query) File "C:\Users\mxmei\anaconda3\Lib\site-packages\xlwings\ext\sql.py", line 68, in _sql return _sql(query, *tables) File "C:\Users\mxmei\anaconda3\Lib\site-packages\xlwings\ext\sql.py", line 28, in sql_dynamic ret = func(*args) File "C:\Users\mxmei\anaconda3\Lib\site-packages\xlwings\udfs.py", line 536, in call_udf res = call_udf(script, fname, args, this_workbook, FromVariant(caller)) File "C:\Users\mxmei\anaconda3\Lib\site-packages\xlwings\com_server.py", line 235, in CallUDF return func(*args) File "C:\Users\mxmei\anaconda3\Lib\site-packages\win32com\server\policy.py", line 633, in _invokeex_ ~~~~~~~~~~~~~~~^^^^^^^^^^^^^^^^^^^^^^^^^^^^^^^^^^^^^^^^ return S_OK, -1, self._invokeex_(dispid, lcid, wFlags, args, None, None) File "C:\Users\mxmei\anaconda3\Lib\site-packages\win32com\server\policy.py", line 303, in _invoke_ ~~~~~~~~~~~~~^^^^^^^^^^^^^^^^^^^^^^^^^^^^ return self._invoke_(dispid, lcid, wFlags, args) File "C:\Users\mxmei\anaconda3\Lib\site-packages\win32com\server\policy.py", line 298, in _Invoke_ | Q29: =$P$25*N29 -> #VALUE!
L30: sqlite3.OperationalError: no such column: key ~~~~~~~~~^^^^^^^ c.execute(query) File "C:\Users\mxmei\anaconda3\Lib\site-packages\xlwings\ext\sql.py", line 68, in _sql return _sql(query, *tables) File "C:\Users\mxmei\anaconda3\Lib\site-packages\xlwings\ext\sql.py", line 28, in sql_dynamic ret = func(*args) File "C:\Users\mxmei\anaconda3\Lib\site-packages\xlwings\udfs.py", line 536, in call_udf res = call_udf(script, fname, args, this_workbook, FromVariant(caller)) File "C:\Users\mxmei\anaconda3\Lib\site-packages\xlwings\com_server.py", line 235, in CallUDF return func(*args) File "C:\Users\mxmei\anaconda3\Lib\site-packages\win32com\server\policy.py", line 633, in _invokeex_ ~~~~~~~~~~~~~~~^^^^^^^^^^^^^^^^^^^^^^^^^^^^^^^^^^^^^^^^ return S_OK, -1, self._invokeex_(dispid, lcid, wFlags, args, None, None) File "C:\Users\mxmei\anaconda3\Lib\site-packages\win32com\server\policy.py", line 303, in _invoke_ ~~~~~~~~~~~~~^^^^^^^^^^^^^^^^^^^^^^^^^^^^ return self._invoke_(dispid, lcid, wFlags, args) File "C:\Users\mxmei\anaconda3\Lib\site-packages\win32com\server\policy.py", line 298, in _Invoke_ | M30: sqlite3.OperationalError: no such column: key ~~~~~~~~~^^^^^^^ c.execute(query) File "C:\Users\mxmei\anaconda3\Lib\site-packages\xlwings\ext\sql.py", line 68, in _sql return _sql(query, *tables) File "C:\Users\mxmei\anaconda3\Lib\site-packages\xlwings\ext\sql.py", line 28, in sql_dynamic ret = func(*args) File "C:\Users\mxmei\anaconda3\Lib\site-packages\xlwings\udfs.py", line 536, in call_udf res = call_udf(script, fname, args, this_workbook, FromVariant(caller)) File "C:\Users\mxmei\anaconda3\Lib\site-packages\xlwings\com_server.py", line 235, in CallUDF return func(*args) File "C:\Users\mxmei\anaconda3\Lib\site-packages\win32com\server\policy.py", line 633, in _invokeex_ ~~~~~~~~~~~~~~~^^^^^^^^^^^^^^^^^^^^^^^^^^^^^^^^^^^^^^^^ return S_OK, -1, self._invokeex_(dispid, lcid, wFlags, args, None, None) File "C:\Users\mxmei\anaconda3\Lib\site-packages\win32com\server\policy.py", line 303, in _invoke_ ~~~~~~~~~~~~~^^^^^^^^^^^^^^^^^^^^^^^^^^^^ return self._invoke_(dispid, lcid, wFlags, args) File "C:\Users\mxmei\anaconda3\Lib\site-packages\win32com\server\policy.py", line 298, in _Invoke_ | N30: sqlite3.OperationalError: no such column: key ~~~~~~~~~^^^^^^^ c.execute(query) File "C:\Users\mxmei\anaconda3\Lib\site-packages\xlwings\ext\sql.py", line 68, in _sql return _sql(query, *tables) File "C:\Users\mxmei\anaconda3\Lib\site-packages\xlwings\ext\sql.py", line 28, in sql_dynamic ret = func(*args) File "C:\Users\mxmei\anaconda3\Lib\site-packages\xlwings\udfs.py", line 536, in call_udf res = call_udf(script, fname, args, this_workbook, FromVariant(caller)) File "C:\Users\mxmei\anaconda3\Lib\site-packages\xlwings\com_server.py", line 235, in CallUDF return func(*args) File "C:\Users\mxmei\anaconda3\Lib\site-packages\win32com\server\policy.py", line 633, in _invokeex_ ~~~~~~~~~~~~~~~^^^^^^^^^^^^^^^^^^^^^^^^^^^^^^^^^^^^^^^^ return S_OK, -1, self._invokeex_(dispid, lcid, wFlags, args, None, None) File "C:\Users\mxmei\anaconda3\Lib\site-packages\win32com\server\policy.py", line 303, in _invoke_ ~~~~~~~~~~~~~^^^^^^^^^^^^^^^^^^^^^^^^^^^^ return self._invoke_(dispid, lcid, wFlags, args) File "C:\Users\mxmei\anaconda3\Lib\site-packages\win32com\server\policy.py", line 298, in _Invoke_ | Q30: =$P$25*N30 -> #VALUE!
L31: sqlite3.OperationalError: no such column: key ~~~~~~~~~^^^^^^^ c.execute(query) File "C:\Users\mxmei\anaconda3\Lib\site-packages\xlwings\ext\sql.py", line 68, in _sql return _sql(query, *tables) File "C:\Users\mxmei\anaconda3\Lib\site-packages\xlwings\ext\sql.py", line 28, in sql_dynamic ret = func(*args) File "C:\Users\mxmei\anaconda3\Lib\site-packages\xlwings\udfs.py", line 536, in call_udf res = call_udf(script, fname, args, this_workbook, FromVariant(caller)) File "C:\Users\mxmei\anaconda3\Lib\site-packages\xlwings\com_server.py", line 235, in CallUDF return func(*args) File "C:\Users\mxmei\anaconda3\Lib\site-packages\win32com\server\policy.py", line 633, in _invokeex_ ~~~~~~~~~~~~~~~^^^^^^^^^^^^^^^^^^^^^^^^^^^^^^^^^^^^^^^^ return S_OK, -1, self._invokeex_(dispid, lcid, wFlags, args, None, None) File "C:\Users\mxmei\anaconda3\Lib\site-packages\win32com\server\policy.py", line 303, in _invoke_ ~~~~~~~~~~~~~^^^^^^^^^^^^^^^^^^^^^^^^^^^^ return self._invoke_(dispid, lcid, wFlags, args) File "C:\Users\mxmei\anaconda3\Lib\site-packages\win32com\server\policy.py", line 298, in _Invoke_ | M31: sqlite3.OperationalError: no such column: key ~~~~~~~~~^^^^^^^ c.execute(query) File "C:\Users\mxmei\anaconda3\Lib\site-packages\xlwings\ext\sql.py", line 68, in _sql return _sql(query, *tables) File "C:\Users\mxmei\anaconda3\Lib\site-packages\xlwings\ext\sql.py", line 28, in sql_dynamic ret = func(*args) File "C:\Users\mxmei\anaconda3\Lib\site-packages\xlwings\udfs.py", line 536, in call_udf res = call_udf(script, fname, args, this_workbook, FromVariant(caller)) File "C:\Users\mxmei\anaconda3\Lib\site-packages\xlwings\com_server.py", line 235, in CallUDF return func(*args) File "C:\Users\mxmei\anaconda3\Lib\site-packages\win32com\server\policy.py", line 633, in _invokeex_ ~~~~~~~~~~~~~~~^^^^^^^^^^^^^^^^^^^^^^^^^^^^^^^^^^^^^^^^ return S_OK, -1, self._invokeex_(dispid, lcid, wFlags, args, None, None) File "C:\Users\mxmei\anaconda3\Lib\site-packages\win32com\server\policy.py", line 303, in _invoke_ ~~~~~~~~~~~~~^^^^^^^^^^^^^^^^^^^^^^^^^^^^ return self._invoke_(dispid, lcid, wFlags, args) File "C:\Users\mxmei\anaconda3\Lib\site-packages\win32com\server\policy.py", line 298, in _Invoke_ | N31: sqlite3.OperationalError: no such column: key ~~~~~~~~~^^^^^^^ c.execute(query) File "C:\Users\mxmei\anaconda3\Lib\site-packages\xlwings\ext\sql.py", line 68, in _sql return _sql(query, *tables) File "C:\Users\mxmei\anaconda3\Lib\site-packages\xlwings\ext\sql.py", line 28, in sql_dynamic ret = func(*args) File "C:\Users\mxmei\anaconda3\Lib\site-packages\xlwings\udfs.py", line 536, in call_udf res = call_udf(script, fname, args, this_workbook, FromVariant(caller)) File "C:\Users\mxmei\anaconda3\Lib\site-packages\xlwings\com_server.py", line 235, in CallUDF return func(*args) File "C:\Users\mxmei\anaconda3\Lib\site-packages\win32com\server\policy.py", line 633, in _invokeex_ ~~~~~~~~~~~~~~~^^^^^^^^^^^^^^^^^^^^^^^^^^^^^^^^^^^^^^^^ return S_OK, -1, self._invokeex_(dispid, lcid, wFlags, args, None, None) File "C:\Users\mxmei\anaconda3\Lib\site-packages\win32com\server\policy.py", line 303, in _invoke_ ~~~~~~~~~~~~~^^^^^^^^^^^^^^^^^^^^^^^^^^^^ return self._invoke_(dispid, lcid, wFlags, args) File "C:\Users\mxmei\anaconda3\Lib\site-packages\win32com\server\policy.py", line 298, in _Invoke_ | Q31: =$P$25*N31 -> #VALUE!
L32: sqlite3.OperationalError: no such column: key ~~~~~~~~~^^^^^^^ c.execute(query) File "C:\Users\mxmei\anaconda3\Lib\site-packages\xlwings\ext\sql.py", line 68, in _sql return _sql(query, *tables) File "C:\Users\mxmei\anaconda3\Lib\site-packages\xlwings\ext\sql.py", line 28, in sql_dynamic ret = func(*args) File "C:\Users\mxmei\anaconda3\Lib\site-packages\xlwings\udfs.py", line 536, in call_udf res = call_udf(script, fname, args, this_workbook, FromVariant(caller)) File "C:\Users\mxmei\anaconda3\Lib\site-packages\xlwings\com_server.py", line 235, in CallUDF return func(*args) File "C:\Users\mxmei\anaconda3\Lib\site-packages\win32com\server\policy.py", line 633, in _invokeex_ ~~~~~~~~~~~~~~~^^^^^^^^^^^^^^^^^^^^^^^^^^^^^^^^^^^^^^^^ return S_OK, -1, self._invokeex_(dispid, lcid, wFlags, args, None, None) File "C:\Users\mxmei\anaconda3\Lib\site-packages\win32com\server\policy.py", line 303, in _invoke_ ~~~~~~~~~~~~~^^^^^^^^^^^^^^^^^^^^^^^^^^^^ return self._invoke_(dispid, lcid, wFlags, args) File "C:\Users\mxmei\anaconda3\Lib\site-packages\win32com\server\policy.py", line 298, in _Invoke_ | M32: sqlite3.OperationalError: no such column: key ~~~~~~~~~^^^^^^^ c.execute(query) File "C:\Users\mxmei\anaconda3\Lib\site-packages\xlwings\ext\sql.py", line 68, in _sql return _sql(query, *tables) File "C:\Users\mxmei\anaconda3\Lib\site-packages\xlwings\ext\sql.py", line 28, in sql_dynamic ret = func(*args) File "C:\Users\mxmei\anaconda3\Lib\site-packages\xlwings\udfs.py", line 536, in call_udf res = call_udf(script, fname, args, this_workbook, FromVariant(caller)) File "C:\Users\mxmei\anaconda3\Lib\site-packages\xlwings\com_server.py", line 235, in CallUDF return func(*args) File "C:\Users\mxmei\anaconda3\Lib\site-packages\win32com\server\policy.py", line 633, in _invokeex_ ~~~~~~~~~~~~~~~^^^^^^^^^^^^^^^^^^^^^^^^^^^^^^^^^^^^^^^^ return S_OK, -1, self._invokeex_(dispid, lcid, wFlags, args, None, None) File "C:\Users\mxmei\anaconda3\Lib\site-packages\win32com\server\policy.py", line 303, in _invoke_ ~~~~~~~~~~~~~^^^^^^^^^^^^^^^^^^^^^^^^^^^^ return self._invoke_(dispid, lcid, wFlags, args) File "C:\Users\mxmei\anaconda3\Lib\site-packages\win32com\server\policy.py", line 298, in _Invoke_ | N32: sqlite3.OperationalError: no such column: key ~~~~~~~~~^^^^^^^ c.execute(query) File "C:\Users\mxmei\anaconda3\Lib\site-packages\xlwings\ext\sql.py", line 68, in _sql return _sql(query, *tables) File "C:\Users\mxmei\anaconda3\Lib\site-packages\xlwings\ext\sql.py", line 28, in sql_dynamic ret = func(*args) File "C:\Users\mxmei\anaconda3\Lib\site-packages\xlwings\udfs.py", line 536, in call_udf res = call_udf(script, fname, args, this_workbook, FromVariant(caller)) File "C:\Users\mxmei\anaconda3\Lib\site-packages\xlwings\com_server.py", line 235, in CallUDF return func(*args) File "C:\Users\mxmei\anaconda3\Lib\site-packages\win32com\server\policy.py", line 633, in _invokeex_ ~~~~~~~~~~~~~~~^^^^^^^^^^^^^^^^^^^^^^^^^^^^^^^^^^^^^^^^ return S_OK, -1, self._invokeex_(dispid, lcid, wFlags, args, None, None) File "C:\Users\mxmei\anaconda3\Lib\site-packages\win32com\server\policy.py", line 303, in _invoke_ ~~~~~~~~~~~~~^^^^^^^^^^^^^^^^^^^^^^^^^^^^ return self._invoke_(dispid, lcid, wFlags, args) File "C:\Users\mxmei\anaconda3\Lib\site-packages\win32com\server\policy.py", line 298, in _Invoke_ | Q32: =$P$25*N32 -> #VALUE!
L33: sqlite3.OperationalError: no such column: key ~~~~~~~~~^^^^^^^ c.execute(query) File "C:\Users\mxmei\anaconda3\Lib\site-packages\xlwings\ext\sql.py", line 68, in _sql return _sql(query, *tables) File "C:\Users\mxmei\anaconda3\Lib\site-packages\xlwings\ext\sql.py", line 28, in sql_dynamic ret = func(*args) File "C:\Users\mxmei\anaconda3\Lib\site-packages\xlwings\udfs.py", line 536, in call_udf res = call_udf(script, fname, args, this_workbook, FromVariant(caller)) File "C:\Users\mxmei\anaconda3\Lib\site-packages\xlwings\com_server.py", line 235, in CallUDF return func(*args) File "C:\Users\mxmei\anaconda3\Lib\site-packages\win32com\server\policy.py", line 633, in _invokeex_ ~~~~~~~~~~~~~~~^^^^^^^^^^^^^^^^^^^^^^^^^^^^^^^^^^^^^^^^ return S_OK, -1, self._invokeex_(dispid, lcid, wFlags, args, None, None) File "C:\Users\mxmei\anaconda3\Lib\site-packages\win32com\server\policy.py", line 303, in _invoke_ ~~~~~~~~~~~~~^^^^^^^^^^^^^^^^^^^^^^^^^^^^ return self._invoke_(dispid, lcid, wFlags, args) File "C:\Users\mxmei\anaconda3\Lib\site-packages\win32com\server\policy.py", line 298, in _Invoke_ | M33: sqlite3.OperationalError: no such column: key ~~~~~~~~~^^^^^^^ c.execute(query) File "C:\Users\mxmei\anaconda3\Lib\site-packages\xlwings\ext\sql.py", line 68, in _sql return _sql(query, *tables) File "C:\Users\mxmei\anaconda3\Lib\site-packages\xlwings\ext\sql.py", line 28, in sql_dynamic ret = func(*args) File "C:\Users\mxmei\anaconda3\Lib\site-packages\xlwings\udfs.py", line 536, in call_udf res = call_udf(script, fname, args, this_workbook, FromVariant(caller)) File "C:\Users\mxmei\anaconda3\Lib\site-packages\xlwings\com_server.py", line 235, in CallUDF return func(*args) File "C:\Users\mxmei\anaconda3\Lib\site-packages\win32com\server\policy.py", line 633, in _invokeex_ ~~~~~~~~~~~~~~~^^^^^^^^^^^^^^^^^^^^^^^^^^^^^^^^^^^^^^^^ return S_OK, -1, self._invokeex_(dispid, lcid, wFlags, args, None, None) File "C:\Users\mxmei\anaconda3\Lib\site-packages\win32com\server\policy.py", line 303, in _invoke_ ~~~~~~~~~~~~~^^^^^^^^^^^^^^^^^^^^^^^^^^^^ return self._invoke_(dispid, lcid, wFlags, args) File "C:\Users\mxmei\anaconda3\Lib\site-packages\win32com\server\policy.py", line 298, in _Invoke_ | N33: sqlite3.OperationalError: no such column: key ~~~~~~~~~^^^^^^^ c.execute(query) File "C:\Users\mxmei\anaconda3\Lib\site-packages\xlwings\ext\sql.py", line 68, in _sql return _sql(query, *tables) File "C:\Users\mxmei\anaconda3\Lib\site-packages\xlwings\ext\sql.py", line 28, in sql_dynamic ret = func(*args) File "C:\Users\mxmei\anaconda3\Lib\site-packages\xlwings\udfs.py", line 536, in call_udf res = call_udf(script, fname, args, this_workbook, FromVariant(caller)) File "C:\Users\mxmei\anaconda3\Lib\site-packages\xlwings\com_server.py", line 235, in CallUDF return func(*args) File "C:\Users\mxmei\anaconda3\Lib\site-packages\win32com\server\policy.py", line 633, in _invokeex_ ~~~~~~~~~~~~~~~^^^^^^^^^^^^^^^^^^^^^^^^^^^^^^^^^^^^^^^^ return S_OK, -1, self._invokeex_(dispid, lcid, wFlags, args, None, None) File "C:\Users\mxmei\anaconda3\Lib\site-packages\win32com\server\policy.py", line 303, in _invoke_ ~~~~~~~~~~~~~^^^^^^^^^^^^^^^^^^^^^^^^^^^^ return self._invoke_(dispid, lcid, wFlags, args) File "C:\Users\mxmei\anaconda3\Lib\site-packages\win32com\server\policy.py", line 298, in _Invoke_ | Q33: =$P$25*N33 -> #VALUE!
L34: sqlite3.OperationalError: no such column: key ~~~~~~~~~^^^^^^^ c.execute(query) File "C:\Users\mxmei\anaconda3\Lib\site-packages\xlwings\ext\sql.py", line 68, in _sql return _sql(query, *tables) File "C:\Users\mxmei\anaconda3\Lib\site-packages\xlwings\ext\sql.py", line 28, in sql_dynamic ret = func(*args) File "C:\Users\mxmei\anaconda3\Lib\site-packages\xlwings\udfs.py", line 536, in call_udf res = call_udf(script, fname, args, this_workbook, FromVariant(caller)) File "C:\Users\mxmei\anaconda3\Lib\site-packages\xlwings\com_server.py", line 235, in CallUDF return func(*args) File "C:\Users\mxmei\anaconda3\Lib\site-packages\win32com\server\policy.py", line 633, in _invokeex_ ~~~~~~~~~~~~~~~^^^^^^^^^^^^^^^^^^^^^^^^^^^^^^^^^^^^^^^^ return S_OK, -1, self._invokeex_(dispid, lcid, wFlags, args, None, None) File "C:\Users\mxmei\anaconda3\Lib\site-packages\win32com\server\policy.py", line 303, in _invoke_ ~~~~~~~~~~~~~^^^^^^^^^^^^^^^^^^^^^^^^^^^^ return self._invoke_(dispid, lcid, wFlags, args) File "C:\Users\mxmei\anaconda3\Lib\site-packages\win32com\server\policy.py", line 298, in _Invoke_ | M34: sqlite3.OperationalError: no such column: key ~~~~~~~~~^^^^^^^ c.execute(query) File "C:\Users\mxmei\anaconda3\Lib\site-packages\xlwings\ext\sql.py", line 68, in _sql return _sql(query, *tables) File "C:\Users\mxmei\anaconda3\Lib\site-packages\xlwings\ext\sql.py", line 28, in sql_dynamic ret = func(*args) File "C:\Users\mxmei\anaconda3\Lib\site-packages\xlwings\udfs.py", line 536, in call_udf res = call_udf(script, fname, args, this_workbook, FromVariant(caller)) File "C:\Users\mxmei\anaconda3\Lib\site-packages\xlwings\com_server.py", line 235, in CallUDF return func(*args) File "C:\Users\mxmei\anaconda3\Lib\site-packages\win32com\server\policy.py", line 633, in _invokeex_ ~~~~~~~~~~~~~~~^^^^^^^^^^^^^^^^^^^^^^^^^^^^^^^^^^^^^^^^ return S_OK, -1, self._invokeex_(dispid, lcid, wFlags, args, None, None) File "C:\Users\mxmei\anaconda3\Lib\site-packages\win32com\server\policy.py", line 303, in _invoke_ ~~~~~~~~~~~~~^^^^^^^^^^^^^^^^^^^^^^^^^^^^ return self._invoke_(dispid, lcid, wFlags, args) File "C:\Users\mxmei\anaconda3\Lib\site-packages\win32com\server\policy.py", line 298, in _Invoke_ | N34: sqlite3.OperationalError: no such column: key ~~~~~~~~~^^^^^^^ c.execute(query) File "C:\Users\mxmei\anaconda3\Lib\site-packages\xlwings\ext\sql.py", line 68, in _sql return _sql(query, *tables) File "C:\Users\mxmei\anaconda3\Lib\site-packages\xlwings\ext\sql.py", line 28, in sql_dynamic ret = func(*args) File "C:\Users\mxmei\anaconda3\Lib\site-packages\xlwings\udfs.py", line 536, in call_udf res = call_udf(script, fname, args, this_workbook, FromVariant(caller)) File "C:\Users\mxmei\anaconda3\Lib\site-packages\xlwings\com_server.py", line 235, in CallUDF return func(*args) File "C:\Users\mxmei\anaconda3\Lib\site-packages\win32com\server\policy.py", line 633, in _invokeex_ ~~~~~~~~~~~~~~~^^^^^^^^^^^^^^^^^^^^^^^^^^^^^^^^^^^^^^^^ return S_OK, -1, self._invokeex_(dispid, lcid, wFlags, args, None, None) File "C:\Users\mxmei\anaconda3\Lib\site-packages\win32com\server\policy.py", line 303, in _invoke_ ~~~~~~~~~~~~~^^^^^^^^^^^^^^^^^^^^^^^^^^^^ return self._invoke_(dispid, lcid, wFlags, args) File "C:\Users\mxmei\anaconda3\Lib\site-packages\win32com\server\policy.py", line 298, in _Invoke_ | Q34: =$P$25*N34 -> #VALUE!
L35: sqlite3.OperationalError: no such column: key ~~~~~~~~~^^^^^^^ c.execute(query) File "C:\Users\mxmei\anaconda3\Lib\site-packages\xlwings\ext\sql.py", line 68, in _sql return _sql(query, *tables) File "C:\Users\mxmei\anaconda3\Lib\site-packages\xlwings\ext\sql.py", line 28, in sql_dynamic ret = func(*args) File "C:\Users\mxmei\anaconda3\Lib\site-packages\xlwings\udfs.py", line 536, in call_udf res = call_udf(script, fname, args, this_workbook, FromVariant(caller)) File "C:\Users\mxmei\anaconda3\Lib\site-packages\xlwings\com_server.py", line 235, in CallUDF return func(*args) File "C:\Users\mxmei\anaconda3\Lib\site-packages\win32com\server\policy.py", line 633, in _invokeex_ ~~~~~~~~~~~~~~~^^^^^^^^^^^^^^^^^^^^^^^^^^^^^^^^^^^^^^^^ return S_OK, -1, self._invokeex_(dispid, lcid, wFlags, args, None, None) File "C:\Users\mxmei\anaconda3\Lib\site-packages\win32com\server\policy.py", line 303, in _invoke_ ~~~~~~~~~~~~~^^^^^^^^^^^^^^^^^^^^^^^^^^^^ return self._invoke_(dispid, lcid, wFlags, args) File "C:\Users\mxmei\anaconda3\Lib\site-packages\win32com\server\policy.py", line 298, in _Invoke_ | M35: sqlite3.OperationalError: no such column: key ~~~~~~~~~^^^^^^^ c.execute(query) File "C:\Users\mxmei\anaconda3\Lib\site-packages\xlwings\ext\sql.py", line 68, in _sql return _sql(query, *tables) File "C:\Users\mxmei\anaconda3\Lib\site-packages\xlwings\ext\sql.py", line 28, in sql_dynamic ret = func(*args) File "C:\Users\mxmei\anaconda3\Lib\site-packages\xlwings\udfs.py", line 536, in call_udf res = call_udf(script, fname, args, this_workbook, FromVariant(caller)) File "C:\Users\mxmei\anaconda3\Lib\site-packages\xlwings\com_server.py", line 235, in CallUDF return func(*args) File "C:\Users\mxmei\anaconda3\Lib\site-packages\win32com\server\policy.py", line 633, in _invokeex_ ~~~~~~~~~~~~~~~^^^^^^^^^^^^^^^^^^^^^^^^^^^^^^^^^^^^^^^^ return S_OK, -1, self._invokeex_(dispid, lcid, wFlags, args, None, None) File "C:\Users\mxmei\anaconda3\Lib\site-packages\win32com\server\policy.py", line 303, in _invoke_ ~~~~~~~~~~~~~^^^^^^^^^^^^^^^^^^^^^^^^^^^^ return self._invoke_(dispid, lcid, wFlags, args) File "C:\Users\mxmei\anaconda3\Lib\site-packages\win32com\server\policy.py", line 298, in _Invoke_ | N35: sqlite3.OperationalError: no such column: key ~~~~~~~~~^^^^^^^ c.execute(query) File "C:\Users\mxmei\anaconda3\Lib\site-packages\xlwings\ext\sql.py", line 68, in _sql return _sql(query, *tables) File "C:\Users\mxmei\anaconda3\Lib\site-packages\xlwings\ext\sql.py", line 28, in sql_dynamic ret = func(*args) File "C:\Users\mxmei\anaconda3\Lib\site-packages\xlwings\udfs.py", line 536, in call_udf res = call_udf(script, fname, args, this_workbook, FromVariant(caller)) File "C:\Users\mxmei\anaconda3\Lib\site-packages\xlwings\com_server.py", line 235, in CallUDF return func(*args) File "C:\Users\mxmei\anaconda3\Lib\site-packages\win32com\server\policy.py", line 633, in _invokeex_ ~~~~~~~~~~~~~~~^^^^^^^^^^^^^^^^^^^^^^^^^^^^^^^^^^^^^^^^ return S_OK, -1, self._invokeex_(dispid, lcid, wFlags, args, None, None) File "C:\Users\mxmei\anaconda3\Lib\site-packages\win32com\server\policy.py", line 303, in _invoke_ ~~~~~~~~~~~~~^^^^^^^^^^^^^^^^^^^^^^^^^^^^ return self._invoke_(dispid, lcid, wFlags, args) File "C:\Users\mxmei\anaconda3\Lib\site-packages\win32com\server\policy.py", line 298, in _Invoke_ | Q35: =$P$25*N35 -> #VALUE!
L36: sqlite3.OperationalError: no such column: key ~~~~~~~~~^^^^^^^ c.execute(query) File "C:\Users\mxmei\anaconda3\Lib\site-packages\xlwings\ext\sql.py", line 68, in _sql return _sql(query, *tables) File "C:\Users\mxmei\anaconda3\Lib\site-packages\xlwings\ext\sql.py", line 28, in sql_dynamic ret = func(*args) File "C:\Users\mxmei\anaconda3\Lib\site-packages\xlwings\udfs.py", line 536, in call_udf res = call_udf(script, fname, args, this_workbook, FromVariant(caller)) File "C:\Users\mxmei\anaconda3\Lib\site-packages\xlwings\com_server.py", line 235, in CallUDF return func(*args) File "C:\Users\mxmei\anaconda3\Lib\site-packages\win32com\server\policy.py", line 633, in _invokeex_ ~~~~~~~~~~~~~~~^^^^^^^^^^^^^^^^^^^^^^^^^^^^^^^^^^^^^^^^ return S_OK, -1, self._invokeex_(dispid, lcid, wFlags, args, None, None) File "C:\Users\mxmei\anaconda3\Lib\site-packages\win32com\server\policy.py", line 303, in _invoke_ ~~~~~~~~~~~~~^^^^^^^^^^^^^^^^^^^^^^^^^^^^ return self._invoke_(dispid, lcid, wFlags, args) File "C:\Users\mxmei\anaconda3\Lib\site-packages\win32com\server\policy.py", line 298, in _Invoke_ | M36: sqlite3.OperationalError: no such column: key ~~~~~~~~~^^^^^^^ c.execute(query) File "C:\Users\mxmei\anaconda3\Lib\site-packages\xlwings\ext\sql.py", line 68, in _sql return _sql(query, *tables) File "C:\Users\mxmei\anaconda3\Lib\site-packages\xlwings\ext\sql.py", line 28, in sql_dynamic ret = func(*args) File "C:\Users\mxmei\anaconda3\Lib\site-packages\xlwings\udfs.py", line 536, in call_udf res = call_udf(script, fname, args, this_workbook, FromVariant(caller)) File "C:\Users\mxmei\anaconda3\Lib\site-packages\xlwings\com_server.py", line 235, in CallUDF return func(*args) File "C:\Users\mxmei\anaconda3\Lib\site-packages\win32com\server\policy.py", line 633, in _invokeex_ ~~~~~~~~~~~~~~~^^^^^^^^^^^^^^^^^^^^^^^^^^^^^^^^^^^^^^^^ return S_OK, -1, self._invokeex_(dispid, lcid, wFlags, args, None, None) File "C:\Users\mxmei\anaconda3\Lib\site-packages\win32com\server\policy.py", line 303, in _invoke_ ~~~~~~~~~~~~~^^^^^^^^^^^^^^^^^^^^^^^^^^^^ return self._invoke_(dispid, lcid, wFlags, args) File "C:\Users\mxmei\anaconda3\Lib\site-packages\win32com\server\policy.py", line 298, in _Invoke_ | N36: sqlite3.OperationalError: no such column: key ~~~~~~~~~^^^^^^^ c.execute(query) File "C:\Users\mxmei\anaconda3\Lib\site-packages\xlwings\ext\sql.py", line 68, in _sql return _sql(query, *tables) File "C:\Users\mxmei\anaconda3\Lib\site-packages\xlwings\ext\sql.py", line 28, in sql_dynamic ret = func(*args) File "C:\Users\mxmei\anaconda3\Lib\site-packages\xlwings\udfs.py", line 536, in call_udf res = call_udf(script, fname, args, this_workbook, FromVariant(caller)) File "C:\Users\mxmei\anaconda3\Lib\site-packages\xlwings\com_server.py", line 235, in CallUDF return func(*args) File "C:\Users\mxmei\anaconda3\Lib\site-packages\win32com\server\policy.py", line 633, in _invokeex_ ~~~~~~~~~~~~~~~^^^^^^^^^^^^^^^^^^^^^^^^^^^^^^^^^^^^^^^^ return S_OK, -1, self._invokeex_(dispid, lcid, wFlags, args, None, None) File "C:\Users\mxmei\anaconda3\Lib\site-packages\win32com\server\policy.py", line 303, in _invoke_ ~~~~~~~~~~~~~^^^^^^^^^^^^^^^^^^^^^^^^^^^^ return self._invoke_(dispid, lcid, wFlags, args) File "C:\Users\mxmei\anaconda3\Lib\site-packages\win32com\server\policy.py", line 298, in _Invoke_ | Q36: =$P$25*N36 -> #VALUE!
L37: sqlite3.OperationalError: no such column: key ~~~~~~~~~^^^^^^^ c.execute(query) File "C:\Users\mxmei\anaconda3\Lib\site-packages\xlwings\ext\sql.py", line 68, in _sql return _sql(query, *tables) File "C:\Users\mxmei\anaconda3\Lib\site-packages\xlwings\ext\sql.py", line 28, in sql_dynamic ret = func(*args) File "C:\Users\mxmei\anaconda3\Lib\site-packages\xlwings\udfs.py", line 536, in call_udf res = call_udf(script, fname, args, this_workbook, FromVariant(caller)) File "C:\Users\mxmei\anaconda3\Lib\site-packages\xlwings\com_server.py", line 235, in CallUDF return func(*args) File "C:\Users\mxmei\anaconda3\Lib\site-packages\win32com\server\policy.py", line 633, in _invokeex_ ~~~~~~~~~~~~~~~^^^^^^^^^^^^^^^^^^^^^^^^^^^^^^^^^^^^^^^^ return S_OK, -1, self._invokeex_(dispid, lcid, wFlags, args, None, None) File "C:\Users\mxmei\anaconda3\Lib\site-packages\win32com\server\policy.py", line 303, in _invoke_ ~~~~~~~~~~~~~^^^^^^^^^^^^^^^^^^^^^^^^^^^^ return self._invoke_(dispid, lcid, wFlags, args) File "C:\Users\mxmei\anaconda3\Lib\site-packages\win32com\server\policy.py", line 298, in _Invoke_ | M37: sqlite3.OperationalError: no such column: key ~~~~~~~~~^^^^^^^ c.execute(query) File "C:\Users\mxmei\anaconda3\Lib\site-packages\xlwings\ext\sql.py", line 68, in _sql return _sql(query, *tables) File "C:\Users\mxmei\anaconda3\Lib\site-packages\xlwings\ext\sql.py", line 28, in sql_dynamic ret = func(*args) File "C:\Users\mxmei\anaconda3\Lib\site-packages\xlwings\udfs.py", line 536, in call_udf res = call_udf(script, fname, args, this_workbook, FromVariant(caller)) File "C:\Users\mxmei\anaconda3\Lib\site-packages\xlwings\com_server.py", line 235, in CallUDF return func(*args) File "C:\Users\mxmei\anaconda3\Lib\site-packages\win32com\server\policy.py", line 633, in _invokeex_ ~~~~~~~~~~~~~~~^^^^^^^^^^^^^^^^^^^^^^^^^^^^^^^^^^^^^^^^ return S_OK, -1, self._invokeex_(dispid, lcid, wFlags, args, None, None) File "C:\Users\mxmei\anaconda3\Lib\site-packages\win32com\server\policy.py", line 303, in _invoke_ ~~~~~~~~~~~~~^^^^^^^^^^^^^^^^^^^^^^^^^^^^ return self._invoke_(dispid, lcid, wFlags, args) File "C:\Users\mxmei\anaconda3\Lib\site-packages\win32com\server\policy.py", line 298, in _Invoke_ | N37: sqlite3.OperationalError: no such column: key ~~~~~~~~~^^^^^^^ c.execute(query) File "C:\Users\mxmei\anaconda3\Lib\site-packages\xlwings\ext\sql.py", line 68, in _sql return _sql(query, *tables) File "C:\Users\mxmei\anaconda3\Lib\site-packages\xlwings\ext\sql.py", line 28, in sql_dynamic ret = func(*args) File "C:\Users\mxmei\anaconda3\Lib\site-packages\xlwings\udfs.py", line 536, in call_udf res = call_udf(script, fname, args, this_workbook, FromVariant(caller)) File "C:\Users\mxmei\anaconda3\Lib\site-packages\xlwings\com_server.py", line 235, in CallUDF return func(*args) File "C:\Users\mxmei\anaconda3\Lib\site-packages\win32com\server\policy.py", line 633, in _invokeex_ ~~~~~~~~~~~~~~~^^^^^^^^^^^^^^^^^^^^^^^^^^^^^^^^^^^^^^^^ return S_OK, -1, self._invokeex_(dispid, lcid, wFlags, args, None, None) File "C:\Users\mxmei\anaconda3\Lib\site-packages\win32com\server\policy.py", line 303, in _invoke_ ~~~~~~~~~~~~~^^^^^^^^^^^^^^^^^^^^^^^^^^^^ return self._invoke_(dispid, lcid, wFlags, args) File "C:\Users\mxmei\anaconda3\Lib\site-packages\win32com\server\policy.py", line 298, in _Invoke_ | Q37: =$P$25*N37 -> #VALUE!

Sheet Wins by Postion
M2: Games | N2: 71 | R2: Games | S2: Picks
M3: D | N3: 22 | O3: 1 | R3: 50 | S3: =P3*$F$19 -> 0
M4: K | N4: 29 | O4: 3 | S4: =P4*$F$19 -> 0
M5: QB | N5: 62 | O5: 25 | S5: =P5*$F$19 -> 0
M6: RB | N6: 55 | O6: 27 | P6: 1 | S6: =P6*$F$19 -> 0
M7: TE | N7: 28 | O7: 0
M8: WR1 | N8: 42 | O8: 7
M9: WR2 | N9: 28 | O9: 1
M10: WR3 | N10: 14 | O10: 2
M11: WR4 | N11: 8

Sheet MVP by Position
K2: {=[1]!sql(SQL!B5,retro)} -> Position | L2: Count | M2: Percentage | O2: Games | P2: Picks
K3: QB | L3: 21 | M3: 0.29577465 | O3: 50 | P3: =M3*$O$3 -> 14.788732
K4: RB | L4: 17 | M4: 0.23943662 | P4: =M4*$O$3 -> 11.971831
K5: WR1 | L5: 15 | M5: 0.21126761 | P5: =M5*$O$3 -> 10.56338
K6: RB1 | L6: 5 | M6: 0.070422535 | P6: =M6*$O$3 -> 3.5211268
K7: K | L7: 4 | M7: 0.056338028 | P7: =M7*$O$3 -> 2.8169014
K8: D | L8: 3 | M8: 0.042253521 | P8: =M8*$O$3 -> 2.1126761
K9: TE | L9: 2 | M9: 0.028169014 | P9: =M9*$O$3 -> 1.4084507
K10: WR2 | L10: 2 | M10: 0.028169014 | P10: =M10*$O$3 -> 1.4084507
K11: RB1Q | L11: 1 | M11: 0.014084507
K12: RB2 | L12: 1 | M12: 0.014084507

Sheet MVP by Player
U2: {=[1]!sql(SQL!B7,retro)} -> Player | V2: Count
U3: D:ATL | V3: 1
U4: QB:ATL | V4: 1
U5: QB:BAL | V5: 4
U6: RB:BAL | V6: 3
U7: QB:BUF | V7: 2
U8: RB:BUF | V8: 1
U9: QB:CIN | V9: 2
U10: WR1:CIN | V10: 4
U11: RB1:CLE | V11: 1
U12: WR1:CLE | V12: 1
U13: QB:DAL | V13: 1
U14: WR1:DAL | V14: 2
... U50: QB:TB | V50: 1

Sheet Team Count
H2: {=[1]!sql(SQL!B9,retro)} -> Team Count | I2: Count | J2: Percentage
H3: 1 | I3: 7 | J3: 0.098591549
H4: 2 | I4: 22 | J4: 0.30985915
H5: 3 | I5: 23 | J5: 0.32394366
H6: 4 | I6: 19 | J6: 0.26760563

Sheet Retro
A1: Winnings | B1: Winners | C1: HS Position | D1: HS MVP | E1: HS Wins | F1: MVP Pts Rank | G1: MVP Position | H1: Key 1 | I1: ID | J1: Group ID | K1: Key 2 | L1: MVP Key | M1: LS Key | N1: MVP_pos | O1: p2_pos | P1: p3_pos | Q1: p4_pos | R1: p5_pos | S1: p6_pos | T1: select | U1: team_cnt | V1: total_salary | W1: total_fppg | X1: total_ppts | Y1: total_pts | Z1: p2_name | AA1: Column1 | AB1: p3_name | AC1: p4_name | AD1: p5_name | AE1: p6_name
D2: =COUNTIF(tRetro[[#This Row],[Key 1]],tRetro[[#This Row],[MVP Key]]) -> 1 | E2: =COUNTIF(tRetro[[#This Row],[Key 1]],"<>"&tRetro[[#This Row],[MVP Key]]) -> 0 | G2: =MID(tRetro[[#This Row],[MVP_pos]],1,FIND(":",tRetro[[#This Row],[MVP_pos]])-1) -> QB | H2: =INT(MID(tRetro[[#This Row],[Key 2]],1,1)) -> 2 | I2: 21341 | J2: 4269 | K2: 2 | L2: 2 | M2: 17 | N2: QB:BAL | O2: RB:KC | P2: WR1:KC | Q2: WR2:KC | R2: TE:BAL | U2: 2 | V2: 56000 | W2: 52.94 | X2: 15 | Y2: 118.18 | Z2: 105733-63115:Lamar Jackson | AA2: 105733-92575:Isiah Pacheco | AB2: 105733-111311:Rashee Rice | AC2: 105733-158974:Xavier Worthy | AD2: 105733-87260:Isaiah Likely
D3: =COUNTIF(tRetro[[#This Row],[Key 1]],tRetro[[#This Row],[MVP Key]]) -> 0 | E3: =COUNTIF(tRetro[[#This Row],[Key 1]],"<>"&tRetro[[#This Row],[MVP Key]]) -> 1 | G3: =MID(tRetro[[#This Row],[MVP_pos]],1,FIND(":",tRetro[[#This Row],[MVP_pos]])-1) -> RB | H3: =INT(MID(tRetro[[#This Row],[Key 2]],1,1)) -> 3 | I3: 18307 | J3: 3662 | K3: 3 | L3: 4 | M3: 15 | N3: RB:PHI | O3: WR1:PHI | P3: WR2:PHI | Q3: WR3:GB | R3: K:GB | U3: 3 | V3: 57500 | W3: 51.15 | X3: 59.95 | Y3: 133.2 | Z3: 106557-64401:Saquon Barkley | AA3: 106557-72846:A.J. Brown | AB3: 106557-90576:DeVonta Smith | AC3: 106557-89455:Jayden Reed | AD3: 106557-85622:Brayden Narveson
D4: =COUNTIF(tRetro[[#This Row],[Key 1]],tRetro[[#This Row],[MVP Key]]) -> 0 | E4: =COUNTIF(tRetro[[#This Row],[Key 1]],"<>"&tRetro[[#This Row],[MVP Key]]) -> 1 | G4: =MID(tRetro[[#This Row],[MVP_pos]],1,FIND(":",tRetro[[#This Row],[MVP_pos]])-1) -> WR1 | H4: =INT(MID(tRetro[[#This Row],[Key 2]],1,1)) -> 4 | I4: 46488 | J4: 9298 | K4: 4 | L4: 8 | M4: 10 | N4: WR1:LAR | O4: QB:LAR | P4: RB2:DET | Q4: WR2:DET | R4: RB1:DET | U4: 2 | V4: 54000 | W4: 61.11 | X4: 61.11 | Y4: 116.78 | Z4: 106609-79970:Cooper Kupp | AA4: 106609-6654:Matthew Stafford | AB4: 106609-129368:Jahmyr Gibbs | AC4: 106609-111631:Jameson Williams | AD4: 106609-73273:David Montgomery
D5: =COUNTIF(tRetro[[#This Row],[Key 1]],tRetro[[#This Row],[MVP Key]]) -> 0 | E5: =COUNTIF(tRetro[[#This Row],[Key 1]],"<>"&tRetro[[#This Row],[MVP Key]]) -> 1 | G5: =MID(tRetro[[#This Row],[MVP_pos]],1,FIND(":",tRetro[[#This Row],[MVP_pos]])-1) -> K | H5: =INT(MID(tRetro[[#This Row],[Key 2]],1,1)) -> 1 | I5: 7478 | J5: 1496 | K5: 1 | L5: 12 | M5: 16 | N5: K:SF | O5: RB:NYJ | P5: WR1:SF | Q5: RB2:SF | R5: WR3:NYJ | U5: 2 | V5: 49500 | W5: 42.83 | X5: 42.83 | Y5: 119.6 | Z5: 106699-91372:Jake Moody | AA5: 106699-103064:Breece Hall | AB5: 106699-56018:Deebo Samuel Sr. | AC5: 106699-86875:Jordan Mason | AD5: 106699-56809:Allen Lazard
D6: =COUNTIF(tRetro[[#This Row],[Key 1]],tRetro[[#This Row],[MVP Key]]) -> 1 | E6: =COUNTIF(tRetro[[#This Row],[Key 1]],"<>"&tRetro[[#This Row],[MVP Key]]) -> 0 | G6: =MID(tRetro[[#This Row],[MVP_pos]],1,FIND(":",tRetro[[#This Row],[MVP_pos]])-1) -> QB | H6: =INT(MID(tRetro[[#This Row],[Key 2]],1,1)) -> 1 | I6: 1876 | J6: 376 | K6: 1 | L6: 1 | M6: 13 | N6: QB:PHI | O6: QB:ATL | P6: WR1:PHI | Q6: K:ATL | R6: WR2:ATL | U6: 2 | V6: 59500 | W6: 44.52 | X6: 44.52 | Y6: 98.17 | Z6: 106989-69531:Jalen Hurts | AA6: 106989-22038:Kirk Cousins | AB6: 106989-90576:DeVonta Smith | AC6: 106989-53212:Younghoe Koo | AD6: 106989-69777:Darnell Mooney
D7: =COUNTIF(tRetro[[#This Row],[Key 1]],tRetro[[#This Row],[MVP Key]]) -> 0 | E7: =COUNTIF(tRetro[[#This Row],[Key 1]],"<>"&tRetro[[#This Row],[MVP Key]]) -> 1 | G7: =MID(tRetro[[#This Row],[MVP_pos]],1,FIND(":",tRetro[[#This Row],[MVP_pos]])-1) -> RB | H7: =INT(MID(tRetro[[#This Row],[Key 2]],1,1)) -> 1 | I7: 8763 | J7: 1753 | K7: 1 | L7: 5 | M7: 16 | N7: RB:BUF | O7: QB:BUF | P7: RB1:MIA | Q7: D:BUF | R7: TE:MIA | U7: 3 | V7: 57500 | W7: 69.68 | X7: 38 | Y7: 104.06 | Z7: 106717-91626:James Cook | AA7: 106717-62239:Josh Allen | AB7: 106717-138820:De'Von Achane | AC7: 106717-12526:Buffalo Bills | AD7: 106717-48116:Jonnu Smith
D8: =COUNTIF(tRetro[[#This Row],[Key 1]],tRetro[[#This Row],[MVP Key]]) -> 0 | E8: =COUNTIF(tRetro[[#This Row],[Key 1]],"<>"&tRetro[[#This Row],[MVP Key]]) -> 1 | G8: =MID(tRetro[[#This Row],[MVP_pos]],1,FIND(":",tRetro[[#This Row],[MVP_pos]])-1) -> WR2 | H8: =INT(MID(tRetro[[#This Row],[Key 2]],1,1)) -> 1 | I8: 7957 | J8: 1592 | K8: 1 | L8: 3 | M8: 14 | N8: WR2:HOU | O8: QB:HOU | P8: K:CHI | Q8: K:HOU | R8: D:HOU | U8: 4 | V8: 56000 | W8: 70.36 | X8: 104.3 | Y8: 100.05 | Z8: 106876-91419:Nico Collins | AA8: 106876-129471:C.J. Stroud | AB8: 106876-33714:Cairo Santos | AC8: 106876-29932:Ka'imi Fairbairn | AD8: 106876-12556:Houston Texans
D9: =COUNTIF(tRetro[[#This Row],[Key 1]],tRetro[[#This Row],[MVP Key]]) -> 1 | E9: =COUNTIF(tRetro[[#This Row],[Key 1]],"<>"&tRetro[[#This Row],[MVP Key]]) -> 0 | G9: =MID(tRetro[[#This Row],[MVP_pos]],1,FIND(":",tRetro[[#This Row],[MVP_pos]])-1) -> QB | H9: =INT(MID(tRetro[[#This Row],[Key 2]],1,1)) -> 1 | I9: 2556 | J9: 512 | K9: 1 | L9: 1 | M9: 22 | N9: QB:BUF | O9: RB:BUF | P9: WR2:BUF | Q9: WR3:JAC | R9: RB3:BUF | U9: 4 | V9: 59000 | W9: 54.42 | X9: 108.8 | Y9: 103.28 | Z9: 107260-62239:Josh Allen | AA9: 107260-91626:James Cook | AB9: 107260-86518:Khalil Shakir | AC9: 107260-60858:Christian Kirk | AD9: 107260-63050:Ty Johnson
D10: =COUNTIF(tRetro[[#This Row],[Key 1]],tRetro[[#This Row],[MVP Key]]) -> 0 | E10: =COUNTIF(tRetro[[#This Row],[Key 1]],"<>"&tRetro[[#This Row],[MVP Key]]) -> 1 | G10: =MID(tRetro[[#This Row],[MVP_pos]],1,FIND(":",tRetro[[#This Row],[MVP_pos]])-1) -> WR1 | H10: =INT(MID(tRetro[[#This Row],[Key 2]],1,1)) -> 1 | I10: 3812 | J10: 763 | K10: 1 | L10: 4 | M10: 11 | N10: WR1:KC | O10: QB:KC | P10: WR1:ATL | Q10: WR2:ATL | R10: K:KC | U10: 3 | V10: 60000 | W10: 58.79 | X10: 114.6 | Y10: 95.83 | Z10: 107208-111311:Rashee Rice | AA10: 107208-57439:Patrick Mahomes | AB10: 107208-112745:Drake London | AC10: 107208-69777:Darnell Mooney | AD10: 107208-41642:Harrison Butker
D11: =COUNTIF(tRetro[[#This Row],[Key 1]],tRetro[[#This Row],[MVP Key]]) -> 0 | E11: =COUNTIF(tRetro[[#This Row],[Key 1]],"<>"&tRetro[[#This Row],[MVP Key]]) -> 1 | G11: =MID(tRetro[[#This Row],[MVP_pos]],1,FIND(":",tRetro[[#This Row],[MVP_pos]])-1) -> QB | H11: =INT(MID(tRetro[[#This Row],[Key 2]],1,1)) -> 1 | I11: 8492 | J11: 1699 | K11: 1 | L11: 3 | M11: 18 | N11: QB:NYJ | O11: RB1:NYJ | P11: WR2:NYJ | Q11: D:NYJ | R11: WR3:NE | U11: 4 | V11: 56500 | W11: 52.41 | X11: 83.1 | Y11: 87.46 | Z11: 107022-6894:Aaron Rodgers | AA11: 107022-103064:Breece Hall | AB11: 107022-56809:Allen Lazard | AC11: 107022-12544:New York Jets | AD11: 107022-111876:DeMario Douglas
D12: =COUNTIF(tRetro[[#This Row],[Key 1]],tRetro[[#This Row],[MVP Key]]) -> 1 | E12: =COUNTIF(tRetro[[#This Row],[Key 1]],"<>"&tRetro[[#This Row],[MVP Key]]) -> 0 | G12: =MID(tRetro[[#This Row],[MVP_pos]],1,FIND(":",tRetro[[#This Row],[MVP_pos]])-1) -> WR1 | H12: =INT(MID(tRetro[[#This Row],[Key 2]],1,1)) -> 1 | I12: 1 | J12: 1 | K12: 1 | L12: 1 | M12: 21 | N12: WR1:CIN | O12: QB:WAS | P12: QB:CIN | Q12: WR1:WAS | R12: RB3:WAS | U12: 2 | V12: 60000 | W12: 44.74 | X12: 82.8 | Y12: 122.22 | Z12: 107261-85701:Ja'Marr Chase | AA12: 107261-102785:Jayden Daniels | AB12: 107261-63336:Joe Burrow | AC12: 107261-56250:Terry McLaurin | AD12: 107261-56648:Jeremy McNichols
D13: =COUNTIF(tRetro[[#This Row],[Key 1]],tRetro[[#This Row],[MVP Key]]) -> 0 | E13: =COUNTIF(tRetro[[#This Row],[Key 1]],"<>"&tRetro[[#This Row],[MVP Key]]) -> 1 | G13: =MID(tRetro[[#This Row],[MVP_pos]],1,FIND(":",tRetro[[#This Row],[MVP_pos]])-1) -> RB | H13: =INT(MID(tRetro[[#This Row],[Key 2]],1,1)) -> 2 | I13: 32747 | J13: 6550 | K13: 2 | L13: 3 | M13: 11 | N13: RB:BAL | O13: QB:BAL | P13: WR1:BUF | Q13: D:BAL | R13: RB:BAL | U13: 4 | V13: 58500 | W13: 67.39 | X13: 67.39 | Y13: 115.54 | Z13: 107485-39280:Derrick Henry | AA13: 107485-63115:Lamar Jackson | AB13: 107485-86518:Khalil Shakir | AC13: 107485-12555:Baltimore Ravens | AD13: 107485-71521:Justice Hill
... D36: =COUNTIF(tRetro[[#This Row],[Key 1]],tRetro[[#This Row],[MVP Key]]) -> 0 | E36: =COUNTIF(tRetro[[#This Row],[Key 1]],"<>"&tRetro[[#This Row],[MVP Key]]) -> 1 | G36: =MID(tRetro[[#This Row],[MVP_pos]],1,FIND(":",tRetro[[#This Row],[MVP_pos]])-1) -> K | H36: =INT(MID(tRetro[[#This Row],[Key 2]],1,1)) -> 2 | I36: 39004 | J36: 7801 | K36: 2 | L36: 11 | M36: 12 | N36: K:LAR | O36: WR1:LAR | P36: WR2:LAR | Q36: QB:LAR | R36: K:MIA | U36: 4 | V36: 58500 | W36: 52.65 | X36: 35 | Y36: 80.02 | Z36: 109359-133172:Joshua Karty | AA36: 109359-79970:Cooper Kupp | AB36: 109359-103020:Puka Nacua | AC36: 109359-6654:Matthew Stafford | AD36: 109359-52767:Jason Sanders
D37: =COUNTIF(tRetro[[#This Row],[Key 1]],tRetro[[#This Row],[MVP Key]]) -> 1 | E37: =COUNTIF(tRetro[[#This Row],[Key 1]],"<>"&tRetro[[#This Row],[MVP Key]]) -> 0 | G37: =MID(tRetro[[#This Row],[MVP_pos]],1,FIND(":",tRetro[[#This Row],[MVP_pos]])-1) -> RB | H37: =INT(MID(tRetro[[#This Row],[Key 2]],1,1)) -> 1 | I37: 1495 | K37: 12 | L37: 1 | M37: 2 | N37: RB:PHI | O37: QB:PHI | P37: RB1:WAS | Q37: RB:WAS | R37: TE:WAS | U37: 2 | V37: 59500 | W37: 76.24 | X37: 86.82 | Y37: 115.44 | Z37: 109392-64401:Saquon Barkley | AA37: 109392-69531:Jalen Hurts | AB37: 109392-90562:Brian Robinson Jr. | AC37: 109392-80001:Austin Ekeler
