Workbook
Name MVPbyPlayer: 'MVP by Player'!$U$2:INDEX(!$R:$R,COUNTA('MVP by Player'!$R:$R))
Name WinsByPosition: 'Position Matrix'!$A$84:$A$93

Sheet Sheet2
A1: Data returned for Count, 13 (First 1000 rows).
A3: tRetro[Winnings] | B3: tRetro[Winners] | C3: tRetro[HS_Pos] | D3: tRetro[HS_MVP] | E3: tRetro[MVP_Rank] | F3: tRetro[ID] | G3: tRetro[GroupID] | H3: tRetro[key] | I3: tRetro[mvp_salary_rank] | J3: tRetro[l_salary_rank] | K3: tRetro[MVP_pos] | L3: tRetro[p2_pos] | M3: tRetro[p3_pos] | N3: tRetro[p4_pos] | O3: tRetro[p5_pos] | P3: tRetro[p6_pos] | Q3: tRetro[select] | R3: tRetro[team_cnt] | S3: tRetro[total_salary] | T3: tRetro[total_fppg] | U3: tRetro[total_ppts] | V3: tRetro[total_pts] | W3: tRetro[MVP_name] | X3: tRetro[p2_name] | Y3: tRetro[p3_name] | Z3: tRetro[p4_name] | AA3: tRetro[p5_name] | AB3: tRetro[p6_name]
A4: 125 | B4: 5 | C4: QB:KC | D4: 0 | E4: 1 | F4: 27863 | G4: 5037 | H4: 13 | I4: 3 | J4: 14 | K4: QB:LAC | L4: QB:KC | M4: WR2:LAC | N4: K:KC | O4: WR3:LAC | P4: WR2:KC | R4: 3 | S4: 57600 | T4: 67.69 | U4: 76.14 | V4: 137 | W4: 120114-69189:Justin Herbert | X4: 120114-57439:Patrick Mahomes | Y4: 120114-29253:Keenan Allen | Z4: 120114-41642:Harrison Butker | AA4: 120114-120639:Quentin Johnston | AB4: 120114-86687:Hollywood Brown
A5: 200 | B5: 2 | C5: QB:TB | D5: 1 | E5: 1 | F5: 14668 | G5: 2884 | H5: 13 | I5: 1 | J5: 42 | K5: QB:TB | L5: RB1:TB | M5: QB1:HOU | N5: RB1:HOU | O5: RB2:TB | P5: QB2:HOU | R5: 3 | S5: 58600 | T5: 52.9 | U5: 64.19 | V5: 96.23 | W5: 120474-41535:Baker Mayfield | X5: 120474-152664:Bucky Irving | Y5: 120474-129471:C.J. Stroud | Z5: 120474-53562:Nick Chubb | AA5: 120474-137902:Rachaad White | AB5: 120474-103591:Graham Mertz
A6: 500 | B6: 1 | C6: QB:BUF | D6: 0 | E6: 2 | F6: 30089 | G6: 5736 | H6: 13 | I6: 3 | J6: 20 | K6: RB1:BUF | L6: QB:BUF | M6: WR1:BUF | N6: WR2:MIA | O6: TE1:BUF | P6: RB2:MIA | R6: 4 | S6: 59400 | T6: 76.89 | U6: 93.8 | V6: 106.27 | W6: 120537-91626:James Cook | X6: 120537-62239:Josh Allen | Y6: 120537-86518:Khalil Shakir | Z6: 120537-90573:Jaylen Waddle | AA6: 120537-145558:Dalton Kincaid | AB6: 120537-166112:Ollie Gordon II
A7: 750 | B7: 1 | C7: RB1:GB | D7: 0 | E7: 1 | F7: 36784 | G7: 6925 | H7: 13 | I7: 3 | J7: 23 | K7: QB:DAL | L7: RB1:GB | M7: WR1:DAL | N7: WR1:GB | O7: K:GB | P7: RB3:GB | R7: 4 | S7: 59800 | T7: 56.47 | U7: 64.47 | V7: 161.44 | W7: 120969-31716:Dak Prescott | X7: 120969-72731:Josh Jacobs | Y7: 120969-110246:George Pickens | Z7: 120969-94370:Romeo Doubs | AA7: 120969-26247:Brandon McManus | AB7: 120969-185861:Emanuel Wilson
A8: 500 | B8: 1 | C8: QB:PHI | D8: 0 | E8: 1 | F8: 8942 | G8: 1883 | H8: 13 | I8: 4 | J8: 47 | K8: RB:NYG | L8: QB:PHI | M8: QB:NYG Q | N8: WR1:NYG | O8: TE:PHI | P8: WR:NYG | R8: 2 | S8: 59700 | T8: 62.65 | U8: 68.75 | V8: 139.62 | W8: 121303-183240:Cam Skattebo | X8: 121303-69531:Jalen Hurts | Y8: 121303-151966:Jaxson Dart | Z8: 121303-103539:Wan'Dale Robinson | AA8: 121303-83074:Dallas Goedert | AB8: 121303-114054:Dalen Cambre
A9: 166.67 | B9: 3 | C9: RB1:DET | D9: 1 | E9: 1 | F9: 18281 | G9: 3478 | H9: 13 | I9: 1 | J9: 18 | K9: RB1:DET | L9: WR1:DET | M9: TE1:TB | N9: D:DET | O9: K:DET | P9: WR5:TB | R9: 4 | S9: 56500 | T9: 58.59 | U9: 66.15 | V9: 118.85 | W9: 121718-129368:Jahmyr Gibbs | X9: 121718-86997:Amon-Ra St. Brown | Y9: 121718-86811:Cade Otton | Z9: 121718-12532:Detroit Lions | AA9: 121718-140176:Jake Bates | AB9: 121718-128624:Tez Johnson

Sheet Wins by Key
G2: Key | H2: Count of Key | Q2: Key | R2: Key 2 | S2: Count of Key 2
G3: 1 | H3: 38 | Q3: 1 | R3: 12 | S3: 10
G4: 2 | H4: 22 | R4: 13 | S4: 4
G5: 3 | H5: 6 | R5: 14 | S5: 3
G6: 4 | H6: 4 | R6: 1 | S6: 20
G7: Grand Total | H7: 70 | R7: 15 | S7: 1
Q8: 2 | R8: 23 | S8: 6
R9: 24 | S9: 1
R10: 27 | S10: 1
R11: 2 | S11: 13
R12: 25 | S12: 1
Q13: 3 | R13: 34 | S13: 3
R14: 3 | S14: 2
R15: 35 | S15: 1
J16: LS Key | K16: Count of LS Key | Q16: 4 | R16: 4 | S16: 4
J17: 8 | K17: 1 | Q17: Grand Total | S17: 70
J18: 9 | K18: 1
J19: 10 | K19: 3
J20: 11 | K20: 7
J21: 12 | K21: 4
J22: 13 | K22: 5
J23: 14 | K23: 5
J24: 15 | K24: 8
J25: 16 | K25: 6
J26: 17 | K26: 7
J27: 18 | K27: 3
J28: 19 | K28: 5
J29: 20 | K29: 3
... J34: 41 | K34: 1
J35: Grand Total | K35: 70

Sheet Wins by Postion
M2: Position | N2: Count 1 | O2: Count 2 | P2: Count 3
M3: Games | P3: =tPositionMatrix[[#Totals],[MVP]] -> 70
M4: D | N4: {=tPositionMatrix[[#Totals],[D]:[D2]]} -> 22 | O4: 1
M5: K | N5: {=tPositionMatrix[[#Totals],[K]:[K2]]} -> 29 | O5: 2
M6: QB | N6: {=tPositionMatrix[[#Totals],[QB]:[QB2]]} -> 61 | O6: 25
M7: RB | N7: {=tPositionMatrix[[#Totals],[RB]:[RB3]]} -> 55 | O7: 27 | P7: 1
M8: TE | N8: {=tPositionMatrix[[#Totals],[TE]:[TE2]]} -> 27 | O8: 0
M9: WR1 | N9: {=tPositionMatrix[[#Totals],[WR1]:[WR12]]} -> 41 | O9: 7
M10: WR2 | N10: {=tPositionMatrix[[#Totals],[WR2]:[WR22]]} -> 27 | O10: 1
M11: WR3 | N11: {=tPositionMatrix[[#Totals],[WR3]:[WR32]]} -> 14 | O11: 2
M12: WR4 | N12: =tPositionMatrix[[#Totals],[WR4]] -> 8

Sheet MVP by Key
G2: Key | H2: Count | R2: MVP Key | S2: Key 2 | T2: Count
G3: 1 | H3: 18 | R3: 1 | S3: 12 | T3: 5
G4: 2 | H4: 16 | S4: 13 | T4: 2
G5: 3 | H5: 6 | S5: 14 | T5: 1
G6: 4 | H6: 11 | S6: 1 | T6: 9
G7: 5 | H7: 4 | S7: 15 | T7: 1
G8: 6 | H8: 3 | R8: 2 | S8: 12 | T8: 4
G9: 8 | H9: 1 | S9: 23 | T9: 5
G10: 9 | H10: 1 | S10: 2 | T10: 6
G11: 12 | H11: 3 | S11: 1 | T11: 1
G12: 7 | H12: 3 | R12: 3 | S12: 13 | T12: 1
G13: 11 | H13: 3 | S13: 2 | T13: 2
G14: 14 | H14: 1 | S14: 1 | T14: 2
G15: Grand Total | H15: 70 | S15: 35 | T15: 1
R16: 4 | S16: 14 | T16: 1
S17: 24 | T17: 1
S18: 34 | T18: 1
G19: Points Rank | H19: Count | S19: 2 | T19: 2
G20: (blank) | S20: 3 | T20: 1
G21: Grand Total | S21: 4 | T21: 1
S22: 1 | T22: 4
R23: 5 | S23: 13 | T23: 1
S24: 34 | T24: 1
S25: 2 | T25: 1
S26: 1 | T26: 1
R27: 6 | S27: 23 | T27: 1
S28: 4 | T28: 1
S29: 1 | T29: 1
R30: 8 | S30: 4 | T30: 1
R31: 9 | S31: 1 | T31: 1
R32: 12 | S32: 14 | T32: 1
S33: 3 | T33: 1
S34: 1 | T34: 1
R35: 7 | S35: 2 | T35: 1
S36: 4 | T36: 1
S37: 25 | T37: 1
R38: 11 | S38: 12 | T38: 1
S39: 27 | T39: 1
S40: 2 | T40: 1
R41: 14 | S41: 34 | T41: 1
...

Sheet MVP by Position
O2: MVP | P2: MVP Position | Q2: Count of MVP Position
O3: D | Q3: 3
O4: K | Q4: 4
O5: QB | Q5: 21
O6: RB | Q6: 24
O7: TE | Q7: 1
O8: WR1 | Q8: 15
O9: WR2 | Q9: 2
O10: Grand Total | Q10: 70

Sheet MVP by Player
R2: MVP_pos | S2: Count of MVP_pos
R3: D:ATL | S3: 1
R4: D:LAR | S4: 1
R5: D:SEA | S5: 1
R6: K:KC | S6: 1
R7: K:LAR | S7: 1
R8: K:SF | S8: 1
R9: K:TEN | S9: 1
R10: QB:ATL | S10: 1
R11: QB:BAL | S11: 4
R12: QB:BUF | S12: 2
R13: QB:CIN | S13: 2
R14: QB:DAL | S14: 1
... R55: Grand Total | S55: 70

Sheet Team Count
B15: Team Count | C15: Count
B16: 1 | C16: 6
B17: 2 | C17: 22
B18: 3 | C18: 23
B19: 4 | C19: 19
B20: Grand Total | C20: 70

Sheet Retro
A1: Winnings | B1: Winners | C1: Place | D1: HS Position | E1: HS MVP | F1: HS Wins | G1: MVP Pts Rank | H1: MVP Position | I1: Key | J1: ID | K1: Group ID | L1: Key 2 | M1: MVP Key | N1: LS Key | O1: MVP_pos | P1: p2_pos | Q1: p3_pos | R1: p4_pos | S1: p5_pos | T1: p6_pos | U1: select | V1: team_cnt | W1: total_salary | X1: total_fppg | Y1: total_ppts | Z1: total_pts | AA1: p2_name | AB1: Column1 | AC1: p3_name | AD1: p4_name | AE1: p5_name | AF1: p6_name
E2: =COUNTIFS(Retro!$I2,1,Retro!$M2,1) -> 0 | F2: =COUNTIFS(Retro!$I2,1,Retro!$M2,"<>1") -> 0 | H2: =MID(Retro!$O2,1,FIND(":",Retro!$O2)-1) -> QB | I2: =INT(MID(Retro!$L2,1,1)) -> 2 | J2: 21341 | K2: 4269 | L2: 2 | M2: 2 | N2: 17 | O2: QB:BAL | P2: RB:KC | Q2: WR1:KC | R2: WR2:KC | S2: TE:BAL | V2: 2 | W2: 56000 | X2: 52.94 | Y2: 15 | Z2: 118.18 | AA2: 105733-63115:Lamar Jackson | AB2: 105733-92575:Isiah Pacheco | AC2: 105733-111311:Rashee Rice | AD2: 105733-158974:Xavier Worthy | AE2: 105733-87260:Isaiah Likely
E3: =COUNTIFS(Retro!$I3,1,Retro!$M3,1) -> 0 | F3: =COUNTIFS(Retro!$I3,1,Retro!$M3,"<>1") -> 0 | H3: =MID(Retro!$O3,1,FIND(":",Retro!$O3)-1) -> RB | I3: =INT(MID(Retro!$L3,1,1)) -> 3 | J3: 18307 | K3: 3662 | L3: 3 | M3: 4 | N3: 15 | O3: RB:PHI | P3: WR1:PHI | Q3: WR2:PHI | R3: WR3:GB | S3: K:GB | V3: 3 | W3: 57500 | X3: 51.15 | Y3: 59.95 | Z3: 133.2 | AA3: 106557-64401:Saquon Barkley | AB3: 106557-72846:A.J. Brown | AC3: 106557-90576:DeVonta Smith | AD3: 106557-89455:Jayden Reed | AE3: 106557-85622:Brayden Narveson
E4: =COUNTIFS(Retro!$I4,1,Retro!$M4,1) -> 0 | F4: =COUNTIFS(Retro!$I4,1,Retro!$M4,"<>1") -> 0 | H4: =MID(Retro!$O4,1,FIND(":",Retro!$O4)-1) -> WR1 | I4: =INT(MID(Retro!$L4,1,1)) -> 4 | J4: 46488 | K4: 9298 | L4: 4 | M4: 8 | N4: 10 | O4: WR1:LAR | P4: QB:LAR | Q4: RB2:DET | R4: WR2:DET | S4: RB1:DET | V4: 2 | W4: 54000 | X4: 61.11 | Y4: 61.11 | Z4: 116.78 | AA4: 106609-79970:Cooper Kupp | AB4: 106609-6654:Matthew Stafford | AC4: 106609-129368:Jahmyr Gibbs | AD4: 106609-111631:Jameson Williams | AE4: 106609-73273:David Montgomery
E5: =COUNTIFS(Retro!$I5,1,Retro!$M5,1) -> 0 | F5: =COUNTIFS(Retro!$I5,1,Retro!$M5,"<>1") -> 1 | H5: =MID(Retro!$O5,1,FIND(":",Retro!$O5)-1) -> K | I5: =INT(MID(Retro!$L5,1,1)) -> 1 | J5: 7478 | K5: 1496 | L5: 1 | M5: 12 | N5: 16 | O5: K:SF | P5: RB:NYJ | Q5: WR1:SF | R5: RB2:SF | S5: WR3:NYJ | V5: 2 | W5: 49500 | X5: 42.83 | Y5: 42.83 | Z5: 119.6 | AA5: 106699-91372:Jake Moody | AB5: 106699-103064:Breece Hall | AC5: 106699-56018:Deebo Samuel Sr. | AD5: 106699-86875:Jordan Mason | AE5: 106699-56809:Allen Lazard
E6: =COUNTIFS(Retro!$I6,1,Retro!$M6,1) -> 1 | F6: =COUNTIFS(Retro!$I6,1,Retro!$M6,"<>1") -> 0 | H6: =MID(Retro!$O6,1,FIND(":",Retro!$O6)-1) -> QB | I6: =INT(MID(Retro!$L6,1,1)) -> 1 | J6: 1876 | K6: 376 | L6: 1 | M6: 1 | N6: 13 | O6: QB:PHI | P6: QB:ATL | Q6: WR1:PHI | R6: K:ATL | S6: WR2:ATL | V6: 2 | W6: 59500 | X6: 44.52 | Y6: 44.52 | Z6: 98.17 | AA6: 106989-69531:Jalen Hurts | AB6: 106989-22038:Kirk Cousins | AC6: 106989-90576:DeVonta Smith | AD6: 106989-53212:Younghoe Koo | AE6: 106989-69777:Darnell Mooney
E7: =COUNTIFS(Retro!$I7,1,Retro!$M7,1) -> 0 | F7: =COUNTIFS(Retro!$I7,1,Retro!$M7,"<>1") -> 1 | H7: =MID(Retro!$O7,1,FIND(":",Retro!$O7)-1) -> RB | I7: =INT(MID(Retro!$L7,1,1)) -> 1 | J7: 8763 | K7: 1753 | L7: 1 | M7: 5 | N7: 16 | O7: RB:BUF | P7: QB:BUF | Q7: RB1:MIA | R7: D:BUF | S7: TE:MIA | V7: 3 | W7: 57500 | X7: 69.68 | Y7: 38 | Z7: 104.06 | AA7: 106717-91626:James Cook | AB7: 106717-62239:Josh Allen | AC7: 106717-138820:De'Von Achane | AD7: 106717-12526:Buffalo Bills | AE7: 106717-48116:Jonnu Smith
E8: =COUNTIFS(Retro!$I8,1,Retro!$M8,1) -> 0 | F8: =COUNTIFS(Retro!$I8,1,Retro!$M8,"<>1") -> 1 | H8: =MID(Retro!$O8,1,FIND(":",Retro!$O8)-1) -> WR2 | I8: =INT(MID(Retro!$L8,1,1)) -> 1 | J8: 7957 | K8: 1592 | L8: 1 | M8: 3 | N8: 14 | O8: WR2:HOU | P8: QB:HOU | Q8: K:CHI | R8: K:HOU | S8: D:HOU | V8: 4 | W8: 56000 | X8: 70.36 | Y8: 104.3 | Z8: 100.05 | AA8: 106876-91419:Nico Collins | AB8: 106876-129471:C.J. Stroud | AC8: 106876-33714:Cairo Santos | AD8: 106876-29932:Ka'imi Fairbairn | AE8: 106876-12556:Houston Texans
E9: =COUNTIFS(Retro!$I9,1,Retro!$M9,1) -> 1 | F9: =COUNTIFS(Retro!$I9,1,Retro!$M9,"<>1") -> 0 | H9: =MID(Retro!$O9,1,FIND(":",Retro!$O9)-1) -> QB | I9: =INT(MID(Retro!$L9,1,1)) -> 1 | J9: 2556 | K9: 512 | L9: 1 | M9: 1 | N9: 22 | O9: QB:BUF | P9: RB:BUF | Q9: WR2:BUF | R9: WR3:JAC | S9: RB3:BUF | V9: 4 | W9: 59000 | X9: 54.42 | Y9: 108.8 | Z9: 103.28 | AA9: 107260-62239:Josh Allen | AB9: 107260-91626:James Cook | AC9: 107260-86518:Khalil Shakir | AD9: 107260-60858:Christian Kirk | AE9: 107260-63050:Ty Johnson
E10: =COUNTIFS(Retro!$I10,1,Retro!$M10,1) -> 0 | F10: =COUNTIFS(Retro!$I10,1,Retro!$M10,"<>1") -> 1 | H10: =MID(Retro!$O10,1,FIND(":",Retro!$O10)-1) -> WR1 | I10: =INT(MID(Retro!$L10,1,1)) -> 1 | J10: 3812 | K10: 763 | L10: 1 | M10: 4 | N10: 11 | O10: WR1:KC | P10: QB:KC | Q10: WR1:ATL | R10: WR2:ATL | S10: K:KC | V10: 3 | W10: 60000 | X10: 58.79 | Y10: 114.6 | Z10: 95.83 | AA10: 107208-111311:Rashee Rice | AB10: 107208-57439:Patrick Mahomes | AC10: 107208-112745:Drake London | AD10: 107208-69777:Darnell Mooney | AE10: 107208-41642:Harrison Butker
E11: =COUNTIFS(Retro!$I11,1,Retro!$M11,1) -> 0 | F11: =COUNTIFS(Retro!$I11,1,Retro!$M11,"<>1") -> 1 | H11: =MID(Retro!$O11,1,FIND(":",Retro!$O11)-1) -> QB | I11: =INT(MID(Retro!$L11,1,1)) -> 1 | J11: 8492 | K11: 1699 | L11: 1 | M11: 3 | N11: 18 | O11: QB:NYJ | P11: RB1:NYJ | Q11: WR2:NYJ | R11: D:NYJ | S11: WR3:NE | V11: 4 | W11: 56500 | X11: 52.41 | Y11: 83.1 | Z11: 87.46 | AA11: 107022-6894:Aaron Rodgers | AB11: 107022-103064:Breece Hall | AC11: 107022-56809:Allen Lazard | AD11: 107022-12544:New York Jets | AE11: 107022-111876:DeMario Douglas
E12: =COUNTIFS(Retro!$I12,1,Retro!$M12,1) -> 1 | F12: =COUNTIFS(Retro!$I12,1,Retro!$M12,"<>1") -> 0 | H12: =MID(Retro!$O12,1,FIND(":",Retro!$O12)-1) -> WR1 | I12: =INT(MID(Retro!$L12,1,1)) -> 1 | J12: 1 | K12: 1 | L12: 1 | M12: 1 | N12: 21 | O12: WR1:CIN | P12: QB:WAS | Q12: QB:CIN | R12: WR1:WAS | S12: RB3:WAS | V12: 2 | W12: 60000 | X12: 44.74 | Y12: 82.8 | Z12: 122.22 | AA12: 107261-85701:Ja'Marr Chase | AB12: 107261-102785:Jayden Daniels | AC12: 107261-63336:Joe Burrow | AD12: 107261-56250:Terry McLaurin | AE12: 107261-56648:Jeremy McNichols
E13: =COUNTIFS(Retro!$I13,1,Retro!$M13,1) -> 0 | F13: =COUNTIFS(Retro!$I13,1,Retro!$M13,"<>1") -> 0 | H13: =MID(Retro!$O13,1,FIND(":",Retro!$O13)-1) -> RB | I13: =INT(MID(Retro!$L13,1,1)) -> 2 | J13: 32747 | K13: 6550 | L13: 2 | M13: 3 | N13: 11 | O13: RB:BAL | P13: QB:BAL | Q13: WR1:BUF | R13: D:BAL | S13: RB:BAL | V13: 4 | W13: 58500 | X13: 67.39 | Y13: 67.39 | Z13: 115.54 | AA13: 107485-39280:Derrick Henry | AB13: 107485-63115:Lamar Jackson | AC13: 107485-86518:Khalil Shakir | AD13: 107485-12555:Baltimore Ravens | AE13: 107485-71521:Justice Hill
... E71: =COUNTIFS(Retro!$I71,1,Retro!$M71,1) -> 0 | F71: =COUNTIFS(Retro!$I71,1,Retro!$M71,"<>1") -> 0 | H71: =MID(Retro!$O71,1,FIND(":",Retro!$O71)-1) -> WR1 | I71: =INT(MID(Retro!$L71,1,1)) -> 2 | J71: 23183 | K71: 4637 | L71: 23 | M71: 6 | N71: 14 | O71: WR1:KC | P71: QB:KC | Q71: QB:PHI | R71: K:PHI | S71: D:PHI | V71: 2 | W71: 56000 | X71: 68.14 | Y71: 68.14 | Z71: 143.87 | AA71: 112626-158974:Xavier Worthy | AB71: 112626-57439:Patrick Mahomes | AC71: 112626-69531:Jalen Hurts | AD71: 112626-41235:Jake Elliott | AE71: 112626-12545:Philadelphia Eagles

Sheet Position Matrix
A1: MVP | B1: D | C1: D2 | D1: K | E1: K2 | F1: QB | G1: QB2 | H1: RB | I1: RB2 | J1: RB3 | K1: TE | L1: TE2 | M1: WR1 | N1: WR12 | O1: WR2 | P1: WR22 | Q1: WR3 | R1: WR32 | S1: WR4
A2: QB:BAL | F2: QB:BAL | H2: RB:KC | K2: TE:BAL | M2: WR1:KC | O2: WR2:KC
A3: RB:PHI | D3: K:GB | H3: RB:PHI | M3: WR1:PHI | O3: WR2:PHI | Q3: WR3:GB
A4: WR1:LAR | F4: QB:LAR | H4: RB1:DET | I4: RB2:DET | M4: WR1:LAR | O4: WR2:DET
A5: K:SF | D5: K:SF | H5: RB:NYJ | I5: RB2:SF | M5: WR1:SF | Q5: WR3:NYJ
A6: QB:PHI | D6: K:ATL | F6: QB:ATL | G6: QB:PHI | M6: WR1:PHI | O6: WR2:ATL
A7: RB:BUF | B7: D:BUF | F7: QB:BUF | H7: RB:BUF | I7: RB1:MIA | K7: TE:MIA
A8: WR2:HOU | B8: D:HOU | D8: K:CHI | E8: K:HOU | F8: QB:HOU | O8: WR2:HOU
A9: QB:BUF | F9: QB:BUF | H9: RB:BUF | I9: RB:BUF | O9: WR2:BUF | Q9: WR3:JAC
A10: WR1:KC | D10: K:KC | F10: QB:KC | M10: WR1:ATL | N10: WR1:KC | O10: WR2:ATL
A11: QB:NYJ | B11: D:NYJ | F11: QB:NYJ | H11: RB1:NYJ | Q11: WR3:NE | R11: WR3:NYJ
A12: WR1:CIN | F12: QB:CIN | G12: QB:WAS | H12: RB:WAS | M12: WR1:CIN | N12: WR1:WAS
A13: RB:BAL | B13: D:BAL | F13: QB:BAL | G13: RB:BAL | H13: RB:BAL | M13: WR1:BUF
A14: WR1:NYG | D14: K:NYG | H14: RB:DAL | M14: WR1:DAL | N14: WR1:NYG | O14: WR2:NYG
A15: WR1:DAL | D15: K:NYG | H15: RB:DAL | M15: WR1:DAL | N15: WR1:NYG | O15: WR2:NYG
A16: RB:SEA | F16: QB:DET | G16: QB:SEA | H16: RB:DET | I16: RB:SEA | K16: TE:SEA
A17: RB:SEA | F17: QB:DET | G17: QB:SEA | H17: RB:DET | I17: RB:SEA | O17: WR2:DET
A18: K:TEN | B18: D:TEN | D18: K:TEN | F18: QB:MIA | H18: RB:TEN | I18: RB:TEN
A19: QB:DAL | F19: QB:DAL | G19: QB:PIT | H19: RB:DAL | K19: TE:PIT | O19: WR2:DAL
A20: RB:KC | D20: K:KC | F20: QB:KC | H20: RB:KC | O20: WR2:NO | P20: WR3:KC
A21: QB:ATL | D21: K:ATL | F21: QB:ATL | G21: QB:TB | M21: WR1:ATL | O21: WR2:ATL
A22: WR1:NYJ | F22: QB:NYJ | H22: RB:BUF | I22: RB:NYJ | M22: WR1:NYJ | O22: WR2:NYJ
A23: QB:CIN | F23: QB:CIN | G23: QB:NYG | H23: RB:CIN | I23: RB:NYG | O23: WR2:NYG
A24: QB:SF | F24: QB:SEA | G24: QB:SF | K24: TE:SF | M24: WR1:SF | Q24: WR3:SEA
A25: QB:BAL | F25: QB:BAL | G25: QB:TB | H25: RB:TB | K25: TE:BAL | O25: WR2:BAL
A26: RB:DEN | B26: D:DEN | D26: K:DEN | F26: QB:DEN | H26: RB:DEN | S26: WR4:NO
A27: RB:NYJ | F27: QB2:PIT | H27: RB:NYJ | I27: RB:PIT | M27: WR1:PIT | Q27: WR3:PIT
A28: WR1:DAL | D28: K:SF | F28: QB:SF | H28: RB:SF | K28: TE1:SF | M28: WR1:DAL
A29: QB:LAR | F29: QB:LAR | H29: RB:LAR | M29: WR1:MIN | Q29: WR3:LAR | S29: WR:LAR
A30: RB2:NYG | B30: D:PIT | H30: RB:PIT | I30: RB2:NYG | Q30: WR3:NYG | R30: WR3:PIT
A31: WR1:NYJ | B31: D:NYJ | F31: QB:NYJ | M31: WR1:HOU | N31: WR1:NYJ | O31: WR2:NYJ
A32: WR1:MIN | B32: D:IND | F32: QB:MIN | K32: TE:MIN | M32: WR1:MIN | O32: WR2:MIN
A33: WR1:KC | F33: QB:KC | H33: RB:KC | I33: RB:KC | K33: TE:TB | M33: WR1:KC
A34: WR1:CIN | F34: QB:BAL | G34: QB:CIN | K34: TE:BAL | M34: WR1:CIN | S34: WR:BAL
A35: RB:HOU | D35: K:HOU | H35: RB:HOU | K35: TE:DET | M35: WR1:DET | S35: WR:HOU
A36: K:LAR | D36: K:LAR | E36: K:MIA | F36: QB:LAR | M36: WR1:LAR | O36: WR2:LAR
A37: RB:PHI | F37: QB:PHI | H37: RB:PHI | I37: RB:WAS | J37: RB1:WAS | K37: TE:WAS
A38: QB:CIN | F38: QB:CIN | G38: QB:LAC | K38: TE:LAC | M38: WR1:LAC | O38: WR2:CIN
A39: RB:HOU | B39: D:HOU | F39: QB:DAL | H39: RB:HOU | M39: WR1:DAL | S39: WR:DAL
A40: RB1:CLE | F40: QB:CLE | G40: QB:PIT | H40: RB:PIT | I40: RB:CLE | Q40: WR3:PIT
...
