Workbook

Sheet FanDuel-NFL-2025 EDT-09 EDT-21 
A1: Id | B1: Position | C1: First Name | D1: Nickname | E1: Last Name | F1: FPPG | G1: Played | H1: Salary | I1: MVP 1.5x Salary | J1: Game | K1: Team | L1: Opponent | M1: Injury Indicator | N1: Injury Details | O1: Tier | P1: Points | Q1: Projected Points | R1: Roster Position
A2: 120720-12536 | B2: D | C2: Kansas City | D2: Kansas City Chiefs | E2: Chiefs | F2: 3 | G2: 2 | H2: 6400 | I2: 9600 | J2: KC@NYG | K2: KC | L2: NYG | O2: 1 | P2: 12 | Q2: 3 | R2: MVP - 1.5X Points/AnyFLEX
A3: 120720-41642 | B3: K | C3: Harrison | D3: Harrison Butker | E3: Butker | F3: 9 | G3: 2 | H3: 6200 | I3: 9300 | J3: KC@NYG | K3: KC | L3: NYG | O3: 1 | P3: 13 | Q3: 9 | R3: MVP - 1.5X Points/AnyFLEX
A4: 120720-57439 | B4: QB | C4: Patrick | D4: Patrick Mahomes | E4: Mahomes | F4: 24.549999 | G4: 2 | H4: 13000 | I4: 19500 | J4: KC@NYG | K4: KC | L4: NYG | O4: 1 | P4: 13.16 | Q4: 24.549999 | R4: MVP - 1.5X Points/AnyFLEX
A5: 120720-61798 | B5: QB | C5: Gardner | D5: Gardner Minshew II | E5: Minshew II | F5: 10.632 | G5: 10 | H5: 1000 | I5: 1500 | J5: KC@NYG | K5: KC | L5: NYG | Q5: 10.632 | R5: MVP - 1.5X Points/AnyFLEX
A6: 120720-73398 | B6: QB | C6: Chris | D6: Chris Oladokun | E6: Oladokun | F6: 0.25 | G6: 2 | H6: 1000 | I6: 1500 | J6: KC@NYG | K6: KC | L6: NYG | Q6: 0.25 | R6: MVP - 1.5X Points/AnyFLEX
A7: 120720-155775 | B7: RB3 | C7: Brashard | D7: Brashard Smith | E7: Smith | F7: 0.1 | G7: 2 | H7: 2400 | I7: 3600 | J7: KC@NYG | K7: KC | L7: NYG | P7: 1.3 | Q7: 0.1 | R7: MVP - 1.5X Points/AnyFLEX
A8: 120720-85741 | B8: RB | C8: Clyde | D8: Clyde Edwards-Helaire | E8: Edwards-Helaire | F8: 2.8333333 | G8: 3 | H8: 1000 | I8: 1500 | J8: KC@NYG | K8: KC | L8: NYG | Q8: 2.8333333 | R8: MVP - 1.5X Points/AnyFLEX
A9: 120720-156523 | B9: RB | C9: Carson | D9: Carson Steele | E9: Steele | F9: 1.5692307 | G9: 13 | H9: 1000 | I9: 1500 | J9: KC@NYG | K9: KC | L9: NYG | Q9: 1.5692307 | R9: MVP - 1.5X Points/AnyFLEX
A10: 120720-92545 | B10: RB | C10: Keaontay | D10: Keaontay Ingram | E10: Ingram | F10: 0 | G10: 1 | H10: 1000 | I10: 1500 | J10: KC@NYG | K10: KC | L10: NYG | M10: IR | N10: Undisclosed | Q10: 0 | R10: MVP - 1.5X Points/AnyFLEX
A11: 120720-92413 | B11: RB | C11: Elijah | D11: Elijah Mitchell | E11: Mitchell | G11: 0 | H11: 1000 | I11: 1500 | J11: KC@NYG | K11: KC | L11: NYG | R11: MVP - 1.5X Points/AnyFLEX
A12: 120720-92575 | B12: RB1 | C12: Isiah | D12: Isiah Pacheco | E12: Pacheco | F12: 3.5999999 | G12: 2 | H12: 6800 | I12: 10200 | J12: KC@NYG | K12: KC | L12: NYG | O12: 1 | P12: 5.3 | Q12: 3.5999999 | R12: MVP - 1.5X Points/AnyFLEX
A13: 120720-45229 | B13: RB2 | C13: Kareem | D13: Kareem Hunt | E13: Hunt | F13: 3.75 | G13: 2 | H13: 5400 | I13: 8100 | J13: KC@NYG | K13: KC | L13: NYG | O13: 1 | P13: 10.9 | Q13: 3.75 | R13: MVP - 1.5X Points/AnyFLEX
A14: 120720-33076 | B14: TE1 | C14: Travis | D14: Travis Kelce | E14: Kelce | F14: 9.8999996 | G14: 2 | H14: 9600 | I14: 14400 | J14: KC@NYG | K14: KC | L14: NYG | O14: 1 | P14: 4.6 | Q14: 9.8999996 | R14: MVP - 1.5X Points/AnyFLEX
A15: 120720-103192 | B15: TE | C15: Jared | D15: Jared Wiley | E15: Wiley | F15: 0.60000002 | G15: 2 | H15: 1000 | I15: 1500 | J15: KC@NYG | K15: KC | L15: NYG | Q15: 0.60000002 | R15: MVP - 1.5X Points/AnyFLEX
A16: 120720-42077 | B16: TE | C16: James | D16: James Winchester | E16: Winchester | F16: 0 | G16: 2 | H16: 1000 | I16: 1500 | J16: KC@NYG | K16: KC | L16: NYG | Q16: 0 | R16: MVP - 1.5X Points/AnyFLEX
A17: 120720-152526 | B17: TE | C17: Jake | D17: Jake Briningstool | E17: Briningstool | G17: 0 | H17: 1000 | I17: 1500 | J17: KC@NYG | K17: KC | L17: NYG | M17: IR | N17: Hamstring | R17: MVP - 1.5X Points/AnyFLEX
A18: 120720-80353 | B18: TE | C18: Robert | D18: Robert Tonyan | E18: Tonyan | G18: 0 | H18: 1000 | I18: 1500 | J18: KC@NYG | K18: KC | L18: NYG | R18: MVP - 1.5X Points/AnyFLEX
A19: 120720-156374 | B19: TE | C19: Tre | D19: Tre Watson | E19: Watson | G19: 0 | H19: 1000 | I19: 1500 | J19: KC@NYG | K19: KC | L19: NYG | R19: MVP - 1.5X Points/AnyFLEX
A20: 120720-93143 | B20: TE2 | C20: Noah | D20: Noah Gray | E20: Gray | F20: 0.69999999 | G20: 2 | H20: 3000 | I20: 4500 | J20: KC@NYG | K20: KC | L20: NYG | P20: 3.2 | Q20: 0.69999999 | R20: MVP - 1.5X Points/AnyFLEX
A21: 120720-176467 | B21: WR | C21: Jalen | D21: Jalen Royals | E21: Royals | G21: 0 | H21: 1800 | I21: 2700 | J21: KC@NYG | K21: KC | L21: NYG | R21: MVP - 1.5X Points/AnyFLEX
A22: 120720-91481 | B22: WR | C22: Nikko | D22: Nikko Remigio | E22: Remigio | F22: 1.3 | G22: 2 | H22: 1600 | I22: 2400 | J22: KC@NYG | K22: KC | L22: NYG | Q22: 1.3 | R22: MVP - 1.5X Points/AnyFLEX | S22: 1.1
A23: 120720-138643 | B23: WR | C23: Jason | D23: Jason Brownlee | E23: Brownlee | F23: 0 | G23: 1 | H23: 1000 | I23: 1500 | J23: KC@NYG | K23: KC | L23: NYG | Q23: 0 | R23: MVP - 1.5X Points/AnyFLEX
A24: 120720-119730 | B24: WR | C24: Jimmy | D24: Jimmy Holiday | E24: Holiday | G24: 0 | H24: 1000 | I24: 1500 | J24: KC@NYG | K24: KC | L24: NYG | R24: MVP - 1.5X Points/AnyFLEX
A25: 120720-158974 | B25: WR1Q | C25: Xavier | D25: Xavier Worthy | E25: Worthy | F25: 0 | G25: 1 | H25: 11000 | I25: 16500 | J25: KC@NYG | K25: KC | L25: NYG | M25: Q | N25: Shoulder - labrum | O25: 1 | Q25: 0 | R25: MVP - 1.5X Points/AnyFLEX
A26: 120720-86687 | B26: WR2 | C26: Hollywood | D26: Hollywood Brown | E26: Brown | F26: 10.2 | G26: 2 | H26: 10400 | I26: 15600 | J26: KC@NYG | K26: KC | L26: NYG | O26: 1 | P26: 6.2 | Q26: 10.2 | R26: MVP - 1.5X Points/AnyFLEX
A27: 120720-89220 | B27: WR3 | C27: Tyquan | D27: Tyquan Thornton | E27: Thornton | F27: 9 | G27: 2 | H27: 5000 | I27: 7500 | J27: KC@NYG | K27: KC | L27: NYG | O27: 1 | P27: 15.6 | Q27: 9 | R27: MVP - 1.5X Points/AnyFLEX
A28: 120720-55987 | B28: WR4 | C28: JuJu | D28: JuJu Smith-Schuster | E28: Smith-Schuster | F28: 4.5 | G28: 2 | H28: 4400 | I28: 6600 | J28: KC@NYG | K28: KC | L28: NYG | O28: 1 | P28: 7.5 | Q28: 4.5 | R28: MVP - 1.5X Points/AnyFLEX
A29: 120720-12543 | B29: D | C29: New York | D29: New York Giants | E29: Giants | F29: 2 | G29: 2 | H29: 5800 | I29: 8700 | J29: KC@NYG | K29: NYG | L29: KC | O29: 1 | P29: 2 | Q29: 2 | R29: MVP - 1.5X Points/AnyFLEX
A30: 120720-10744 | B30: K | C30: Graham | D30: Graham Gano | E30: Gano | F30: 10.5 | G30: 2 | H30: 6000 | I30: 9000 | J30: KC@NYG | K30: NYG | L30: KC | O30: 1 | P30: 3 | Q30: 10.5 | R30: MVP - 1.5X Points/AnyFLEX
A31: 120720-176119 | B31: K | C31: Jude | D31: Jude McAtamney | E31: McAtamney | F31: 4 | G31: 1 | H31: 1000 | I31: 1500 | J31: KC@NYG | K31: NYG | L31: KC | Q31: 4 | R31: MVP - 1.5X Points/AnyFLEX
A32: 120720-22015 | B32: QB | C32: Russell | D32: Russell Wilson | E32: Wilson | F32: 22.709999 | G32: 2 | H32: 12000 | I32: 18000 | J32: KC@NYG | K32: NYG | L32: KC | O32: 1 | P32: 7.1 | Q32: 22.709999 | R32: MVP - 1.5X Points/AnyFLEX
A33: 120720-24849 | B33: QB | C33: Jameis | D33: Jameis Winston | E33: Winston | F33: 13.830909 | G33: 11 | H33: 1000 | I33: 1500 | J33: KC@NYG | K33: NYG | L33: KC | Q33: 13.830909 | R33: MVP - 1.5X Points/AnyFLEX
A34: 120720-151966 | B34: QB | C34: Jaxson | D34: Jaxson Dart | E34: Dart | F34: -0.30000001 | G34: 1 | H34: 1000 | I34: 1500 | J34: KC@NYG | K34: NYG | L34: KC | Q34: -0.30000001 | R34: MVP - 1.5X Points/AnyFLEX | S34: 0.3
A35: 120720-70603 | B35: RB | C35: Devin | D35: Devin Singletary | E35: Singletary | F35: 0.69999999 | G35: 2 | H35: 4800 | I35: 7200 | J35: KC@NYG | K35: NYG | L35: KC | Q35: 0.69999999 | R35: MVP - 1.5X Points/AnyFLEX | S35: 1.1
A36: 120720-173631 | B36: RB | C36: Dante | D36: Dante Miller | E36: Miller | G36: 0 | H36: 1000 | I36: 1500 | J36: KC@NYG | K36: NYG | L36: KC | R36: MVP - 1.5X Points/AnyFLEX
A37: 120720-86153 | B37: RB1 | C37: Tyrone | D37: Tyrone Tracy Jr. | E37: Tracy Jr. | F37: 5.8000002 | G37: 2 | H37: 7800 | I37: 11700 | J37: KC@NYG | K37: NYG | L37: KC | M37: Q | N37: Calf | O37: 1 | P37: 4.6 | Q37: 5.8000002 | R37: MVP - 1.5X Points/AnyFLEX
A38: 120720-183240 | B38: RB2 | C38: Cam | D38: Cam Skattebo | E38: Skattebo | F38: 7.4000001 | G38: 2 | H38: 7200 | I38: 10800 | J38: KC@NYG | K38: NYG | L38: KC | O38: 1 | P38: 21.1 | Q38: 7.4000001 | R38: MVP - 1.5X Points/AnyFLEX
A39: 120720-128810 | B39: TE1 | C39: Theo | D39: Theo Johnson | E39: Johnson | F39: 3.2 | G39: 2 | H39: 4000 | I39: 6000 | J39: KC@NYG | K39: NYG | L39: KC | O39: 1 | P39: 1.5 | Q39: 3.2 | R39: MVP - 1.5X Points/AnyFLEX
A40: 120720-90307 | B40: TE | C40: Daniel | D40: Daniel Bellinger | E40: Bellinger | F40: 1.9 | G40: 1 | H40: 2000 | I40: 3000 | J40: KC@NYG | K40: NYG | L40: KC | Q40: 1.9 | R40: MVP - 1.5X Points/AnyFLEX | S40: 1.1
...

Sheet Sheet1
A1: Patrick Mahomes | B1: =INDEX('FanDuel-NFL-2025 EDT-09 EDT-21 '!B:B,MATCH(A1,'FanDuel-NFL-2025 EDT-09 EDT-21 '!D:D,0),1) -> QB | C1: KC | D1: 26 | E1: 23.1 | F1: =B1&":"&C1 -> QB:KC | G1: =MIN(D1:E1) -> 23.1 | H1: =MAX(D1:E1) -> 26
A2: Russell Wilson | B2: =INDEX('FanDuel-NFL-2025 EDT-09 EDT-21 '!B:B,MATCH(A2,'FanDuel-NFL-2025 EDT-09 EDT-21 '!D:D,0),1) -> QB | C2: NYG | D2: 11.1 | E2: 31.3 | F2: =B2&":"&C2 -> QB:NYG | G2: =MIN(D2:E2) -> 11.1 | H2: =MAX(D2:E2) -> 31.3
A3: Malik Nabers | B3: =INDEX('FanDuel-NFL-2025 EDT-09 EDT-21 '!B:B,MATCH(A3,'FanDuel-NFL-2025 EDT-09 EDT-21 '!D:D,0),1) -> WR1 | C3: NYG | D3: 7.1 | E3: 28.7 | F3: =B3&":"&C3 -> WR1:NYG | G3: =MIN(D3:E3) -> 7.1 | H3: =MAX(D3:E3) -> 28.7
A4: Wan'Dale Robinson | B4: =INDEX('FanDuel-NFL-2025 EDT-09 EDT-21 '!B:B,MATCH(A4,'FanDuel-NFL-2025 EDT-09 EDT-21 '!D:D,0),1) -> WR2 | C4: NYG | D4: 5.5 | E4: 20.2 | F4: =B4&":"&C4 -> WR2:NYG | G4: =MIN(D4:E4) -> 5.5 | H4: =MAX(D4:E4) -> 20.2
A5: Graham Gano | B5: =INDEX('FanDuel-NFL-2025 EDT-09 EDT-21 '!B:B,MATCH(A5,'FanDuel-NFL-2025 EDT-09 EDT-21 '!D:D,0),1) -> K | C5: NYG | D5: 8 | E5: 13 | F5: =B5&":"&C5 -> K:NYG | G5: =MIN(D5:E5) -> 8 | H5: =MAX(D5:E5) -> 13
A6: Harrison Butker | B6: =INDEX('FanDuel-NFL-2025 EDT-09 EDT-21 '!B:B,MATCH(A6,'FanDuel-NFL-2025 EDT-09 EDT-21 '!D:D,0),1) -> K | C6: KC | D6: 11 | E6: 7 | F6: =B6&":"&C6 -> K:KC | G6: =MIN(D6:E6) -> 7 | H6: =MAX(D6:E6) -> 11
A7: Travis Kelce | B7: =INDEX('FanDuel-NFL-2025 EDT-09 EDT-21 '!B:B,MATCH(A7,'FanDuel-NFL-2025 EDT-09 EDT-21 '!D:D,0),1) -> TE1 | C7: KC | D7: 10.7 | E7: 6.1 | F7: =B7&":"&C7 -> TE1:KC | G7: =MIN(D7:E7) -> 6.1 | H7: =MAX(D7:E7) -> 10.7
A8: Tyquan Thornton | B8: =INDEX('FanDuel-NFL-2025 EDT-09 EDT-21 '!B:B,MATCH(A8,'FanDuel-NFL-2025 EDT-09 EDT-21 '!D:D,0),1) -> WR3 | C8: KC | D8: 4.1 | E8: 11.9 | F8: =B8&":"&C8 -> WR3:KC | G8: =MIN(D8:E8) -> 4.1 | H8: =MAX(D8:E8) -> 11.9
A9: Hollywood Brown | B9: =INDEX('FanDuel-NFL-2025 EDT-09 EDT-21 '!B:B,MATCH(A9,'FanDuel-NFL-2025 EDT-09 EDT-21 '!D:D,0),1) -> WR2 | C9: KC | D9: 9.9 | E9: 3 | F9: =B9&":"&C9 -> WR2:KC | G9: =MIN(D9:E9) -> 3 | H9: =MAX(D9:E9) -> 9.9
A10: Cam Skattebo | B10: =INDEX('FanDuel-NFL-2025 EDT-09 EDT-21 '!B:B,MATCH(A10,'FanDuel-NFL-2025 EDT-09 EDT-21 '!D:D,0),1) -> RB2 | C10: NYG | D10: 0.9 | E10: 11.9 | F10: =B10&":"&C10 -> RB2:NYG | G10: =MIN(D10:E10) -> 0.9 | H10: =MAX(D10:E10) -> 11.9
A11: Tyrone Tracy Jr. | B11: =INDEX('FanDuel-NFL-2025 EDT-09 EDT-21 '!B:B,MATCH(A11,'FanDuel-NFL-2025 EDT-09 EDT-21 '!D:D,0),1) -> RB1 | C11: NYG | D11: 3.5 | E11: 5.1 | F11: =B11&":"&C11 -> RB1:NYG | G11: =MIN(D11:E11) -> 3.5 | H11: =MAX(D11:E11) -> 5.1
A12: Darius Slayton | B12: =INDEX('FanDuel-NFL-2025 EDT-09 EDT-21 '!B:B,MATCH(A12,'FanDuel-NFL-2025 EDT-09 EDT-21 '!D:D,0),1) -> WR3 | C12: NYG | D12: 0 | E12: 6.1 | F12: =B12&":"&C12 -> WR3:NYG | G12: =MIN(D12:E12) -> 0 | H12: =MAX(D12:E12) -> 6.1
... A23: Brashard Smith | B23: =INDEX('FanDuel-NFL-2025 EDT-09 EDT-21 '!B:B,MATCH(A23,'FanDuel-NFL-2025 EDT-09 EDT-21 '!D:D,0),1) -> RB3 | C23: KC | D23: 0 | E23: 0.2 | F23: =B23&":"&C23 -> RB3:KC | G23: =MIN(D23:E23) -> 0 | H23: =MAX(D23:E23) -> 0.2
A24: James Winchester | B24: =INDEX('FanDuel-NFL-2025 EDT-09 EDT-21 '!B:B,MATCH(A24,'FanDuel-NFL-2025 EDT-09 EDT-21 '!D:D,0),1) -> TE | C24: KC | D24: - | E24: 0 | F24: =B24&":"&C24 -> TE:KC | G24: =MIN(D24:E24) -> 0 | H24: =MAX(D24:E24) -> 0
A25: Beaux Collins | B25: =INDEX('FanDuel-NFL-2025 EDT-09 EDT-21 '!B:B,MATCH(A25,'FanDuel-NFL-2025 EDT-09 EDT-21 '!D:D,0),1) -> WR5 | C25: NYG | D25: 0 | E25: 0 | F25: =B25&":"&C25 -> WR5:NYG | G25: =MIN(D25:E25) -> 0 | H25: =MAX(D25:E25) -> 0
A26: Gunner Olszewski | B26: =INDEX('FanDuel-NFL-2025 EDT-09 EDT-21 '!B:B,MATCH(A26,'FanDuel-NFL-2025 EDT-09 EDT-21 '!D:D,0),1) -> WR | C26: NYG | D26: 0 | E26: 0 | F26: =B26&":"&C26 -> WR:NYG | G26: =MIN(D26:E26) -> 0 | H26: =MAX(D26:E26) -> 0
A27: Xavier Worthy | B27: =INDEX('FanDuel-NFL-2025 EDT-09 EDT-21 '!B:B,MATCH(A27,'FanDuel-NFL-2025 EDT-09 EDT-21 '!D:D,0),1) -> WR1Q | C27: KC | D27: 0 | E27: - | F27: =B27&":"&C27 -> WR1Q:KC | G27: =MIN(D27:E27) -> 0 | H27: =MAX(D27:E27) -> 0
A28: Jason Brownlee | B28: =INDEX('FanDuel-NFL-2025 EDT-09 EDT-21 '!B:B,MATCH(A28,'FanDuel-NFL-2025 EDT-09 EDT-21 '!D:D,0),1) -> WR | C28: KC | D28: 0 | E28: 0 | F28: =B28&":"&C28 -> WR:KC | G28: =MIN(D28:E28) -> 0 | H28: =MAX(D28:E28) -> 0
A29: Chris Manhertz | B29: =INDEX('FanDuel-NFL-2025 EDT-09 EDT-21 '!B:B,MATCH(A29,'FanDuel-NFL-2025 EDT-09 EDT-21 '!D:D,0),1) -> TE2 | C29: NYG | D29: 0 | E29: 0 | F29: =B29&":"&C29 -> TE2:NYG | G29: =MIN(D29:E29) -> 0 | H29: =MAX(D29:E29) -> 0
A30: Robert Tonyan | B30: =INDEX('FanDuel-NFL-2025 EDT-09 EDT-21 '!B:B,MATCH(A30,'FanDuel-NFL-2025 EDT-09 EDT-21 '!D:D,0),1) -> TE | C30: KC | D30: 0 | E30: 0 | F30: =B30&":"&C30 -> TE:KC | G30: =MIN(D30:E30) -> 0 | H30: =MAX(D30:E30) -> 0
A31: Jaxson Dart | B31: =INDEX('FanDuel-NFL-2025 EDT-09 EDT-21 '!B:B,MATCH(A31,'FanDuel-NFL-2025 EDT-09 EDT-21 '!D:D,0),1) -> QB | C31: NYG | D31: - | E31: -0.3 | F31: =B31&":"&C31 -> QB:NYG | G31: =MIN(D31:E31) -> -0.3 | H31: =MAX(D31:E31) -> -0.3
A32: Xavier Gipson | B32: =INDEX('FanDuel-NFL-2025 EDT-09 EDT-21 '!B:B,MATCH(A32,'FanDuel-NFL-2025 EDT-09 EDT-21 '!D:D,0),1) -> WR | C32: NYG | D32: -2 | E32: - | F32: =B32&":"&C32 -> WR:NYG | G32: =MIN(D32:E32) -> -2 | H32: =MAX(D32:E32) -> -2
A33: Jalin Hyatt | F33: WR4:NYG | G33: 0 | H33: 0.92727271
