Workbook

Sheet FanDuel-NFL-2024 ET-10 ET-13 ET
A1: Id | B1: Position | C1: First Name | D1: Nickname | E1: Last Name | F1: FPPG | G1: Played | H1: Salary | I1: Salary | J1: Game | K1: Team | L1: Opponent | M1: Injury Indicator | N1: Injury Details | O1: Tier | P1: Points | Q1: Projected Points | R1: Roster Position
A2: 108048-12528 | B2: D | C2: Cincinnati | D2: Cincinnati Bengals | E2: Bengals | F2: 2.4 | G2: 5 | H2: 8000 | I2: 8000 | J2: CIN@NYG | K2: CIN | L2: NYG | O2: 1 | P2: 8 | Q2: =INDEX(Sheet1!A:B,MATCH(D2,Sheet1!A:A,0),2) -> 12 | R2: MVP - 1.5X Points/AnyFLEX
A3: 108048-86092 | B3: K | C3: Evan | D3: Evan McPherson | E3: McPherson | F3: 9.6 | G3: 5 | H3: 9000 | I3: 9000 | J3: CIN@NYG | K3: CIN | L3: NYG | O3: 1 | P3: 5 | Q3: =INDEX(Sheet1!A:B,MATCH(D3,Sheet1!A:A,0),2) -> 48 | R3: MVP - 1.5X Points/AnyFLEX
A4: 108048-63336 | B4: QB | C4: Joe | D4: Joe Burrow | E4: Burrow | F4: 21.739999 | G4: 5 | H4: 16000 | I4: 16000 | J4: CIN@NYG | K4: CIN | L4: NYG | O4: 1 | P4: 19.82 | Q4: =INDEX(Sheet1!A:B,MATCH(D4,Sheet1!A:A,0),2) -> 102.7 | R4: MVP - 1.5X Points/AnyFLEX
A5: 108048-60840 | B5: QB | C5: Jake | D5: Jake Browning | E5: Browning | F5: 12.578334 | G5: 12 | H5: 5000 | I5: 5000 | J5: CIN@NYG | K5: CIN | L5: NYG | Q5: =INDEX(Sheet1!A:B,MATCH(D5,Sheet1!A:A,0),2) -> #N/A | R5: MVP - 1.5X Points/AnyFLEX
A6: 108048-92904 | B6: QB | C6: Rocky | D6: Rocky Lombardi | E6: Lombardi | G6: 0 | H6: 5000 | I6: 5000 | J6: CIN@NYG | K6: CIN | L6: NYG | Q6: =INDEX(Sheet1!A:B,MATCH(D6,Sheet1!A:A,0),2) -> #N/A | R6: MVP - 1.5X Points/AnyFLEX
A7: 108048-45259 | B7: QB | C7: Logan | D7: Logan Woodside | E7: Woodside | F7: 0.34 | G7: 2 | H7: 5000 | I7: 5000 | J7: CIN@NYG | K7: CIN | L7: NYG | Q7: =INDEX(Sheet1!A:B,MATCH(D7,Sheet1!A:A,0),2) -> #N/A | R7: MVP - 1.5X Points/AnyFLEX
A8: 108048-89493 | B8: RB | C8: Chase | D8: Chase Brown | E8: Brown | F8: 10.38 | G8: 5 | H8: 10500 | I8: 10500 | J8: CIN@NYG | K8: CIN | L8: NYG | M8: Q | N8: Quadriceps | O8: 1 | P8: 13.4 | Q8: =INDEX(Sheet1!A:B,MATCH(D8,Sheet1!A:A,0),2) -> 51.9 | R8: MVP - 1.5X Points/AnyFLEX
A9: 108048-70027 | B9: RB | C9: Zack | D9: Zack Moss | E9: Moss | F9: 11.8 | G9: 5 | H9: 10000 | I9: 10000 | J9: CIN@NYG | K9: CIN | L9: NYG | P9: 0 | Q9: =INDEX(Sheet1!A:B,MATCH(D9,Sheet1!A:A,0),2) -> 59 | R9: MVP - 1.5X Points/AnyFLEX
A10: 108048-69860 | B10: RB | C10: Trayveon | D10: Trayveon Williams | E10: Williams | F10: 0 | G10: 3 | H10: 5500 | I10: 5500 | J10: CIN@NYG | K10: CIN | L10: NYG | Q10: =INDEX(Sheet1!A:B,MATCH(D10,Sheet1!A:A,0),2) -> 0 | R10: MVP - 1.5X Points/AnyFLEX
A11: 108048-103584 | B11: RB | C11: Noah | D11: Noah Cain | E11: Cain | G11: 0 | H11: 5000 | I11: 5000 | J11: CIN@NYG | K11: CIN | L11: NYG | Q11: =INDEX(Sheet1!A:B,MATCH(D11,Sheet1!A:A,0),2) -> #N/A | R11: MVP - 1.5X Points/AnyFLEX
A12: 108048-92891 | B12: RB | C12: Elijah | D12: Elijah Collins | E12: Collins | G12: 0 | H12: 5000 | I12: 5000 | J12: CIN@NYG | K12: CIN | L12: NYG | Q12: =INDEX(Sheet1!A:B,MATCH(D12,Sheet1!A:A,0),2) -> #N/A | R12: MVP - 1.5X Points/AnyFLEX
A13: 108048-73130 | B13: RB | C13: Chris | D13: Chris Evans | E13: Evans | F13: 0.40000001 | G13: 4 | H13: 5000 | I13: 5000 | J13: CIN@NYG | K13: CIN | L13: NYG | M13: IR | N13: Leg | Q13: =INDEX(Sheet1!A:B,MATCH(D13,Sheet1!A:A,0),2) -> #N/A | R13: MVP - 1.5X Points/AnyFLEX
A14: 108048-119672 | B14: RB | C14: Kendall | D14: Kendall Milton | E14: Milton | G14: 0 | H14: 5000 | I14: 5000 | J14: CIN@NYG | K14: CIN | L14: NYG | Q14: =INDEX(Sheet1!A:B,MATCH(D14,Sheet1!A:A,0),2) -> #N/A | R14: MVP - 1.5X Points/AnyFLEX
A15: 108048-56265 | B15: TE | C15: Mike | D15: Mike Gesicki | E15: Gesicki | F15: 5.2599998 | G15: 5 | H15: 7500 | I15: 7500 | J15: CIN@NYG | K15: CIN | L15: NYG | Q15: =INDEX(Sheet1!A:B,MATCH(D15,Sheet1!A:A,0),2) -> 26.3 | R15: MVP - 1.5X Points/AnyFLEX
A16: 108048-103378 | B16: TE | C16: Erick | D16: Erick All Jr. | E16: All Jr. | F16: 4.0500002 | G16: 4 | H16: 7000 | I16: 7000 | J16: CIN@NYG | K16: CIN | L16: NYG | O16: 1 | P16: 2 | Q16: =INDEX(Sheet1!A:B,MATCH(D16,Sheet1!A:A,0),2) -> 16.2 | R16: MVP - 1.5X Points/AnyFLEX
A17: 108048-56711 | B17: TE | C17: Drew | D17: Drew Sample | E17: Sample | F17: 2.4000001 | G17: 2 | H17: 6000 | I17: 6000 | J17: CIN@NYG | K17: CIN | L17: NYG | Q17: =INDEX(Sheet1!A:B,MATCH(D17,Sheet1!A:A,0),2) -> 4.8 | R17: MVP - 1.5X Points/AnyFLEX
A18: 108048-92056 | B18: TE | C18: Cal | D18: Cal Adomitis | E18: Adomitis | F18: 0 | G18: 2 | H18: 5000 | I18: 5000 | J18: CIN@NYG | K18: CIN | L18: NYG | Q18: =INDEX(Sheet1!A:B,MATCH(D18,Sheet1!A:A,0),2) -> #N/A | R18: MVP - 1.5X Points/AnyFLEX
A19: 108048-201564 | B19: TE | C19: Cam | D19: Cam Grandy | E19: Grandy | G19: 0 | H19: 5000 | I19: 5000 | J19: CIN@NYG | K19: CIN | L19: NYG | Q19: =INDEX(Sheet1!A:B,MATCH(D19,Sheet1!A:A,0),2) -> #N/A | R19: MVP - 1.5X Points/AnyFLEX
A20: 108048-83117 | B20: TE | C20: Tanner | D20: Tanner Hudson | E20: Hudson | F20: 0.80000001 | G20: 1 | H20: 5000 | I20: 5000 | J20: CIN@NYG | K20: CIN | L20: NYG | Q20: =INDEX(Sheet1!A:B,MATCH(D20,Sheet1!A:A,0),2) -> 0.8 | R20: MVP - 1.5X Points/AnyFLEX
A21: 108048-160463 | B21: TE | C21: Tanner | D21: Tanner McLachlan | E21: McLachlan | G21: 0 | H21: 5000 | I21: 5000 | J21: CIN@NYG | K21: CIN | L21: NYG | Q21: =INDEX(Sheet1!A:B,MATCH(D21,Sheet1!A:A,0),2) -> #N/A | R21: MVP - 1.5X Points/AnyFLEX
A22: 108048-133484 | B22: WR | C22: Jermaine | D22: Jermaine Burton | E22: Burton | F22: 5.1999998 | G22: 1 | H22: 6500 | I22: 6500 | J22: CIN@NYG | K22: CIN | L22: NYG | Q22: =INDEX(Sheet1!A:B,MATCH(D22,Sheet1!A:A,0),2) -> 5.2 | R22: MVP - 1.5X Points/AnyFLEX
A23: 108048-64905 | B23: WR | C23: Trenton | D23: Trenton Irwin | E23: Irwin | F23: 1.05 | G23: 2 | H23: 6000 | I23: 6000 | J23: CIN@NYG | K23: CIN | L23: NYG | Q23: =INDEX(Sheet1!A:B,MATCH(D23,Sheet1!A:A,0),2) -> 2.1 | R23: MVP - 1.5X Points/AnyFLEX
A24: 108048-88752 | B24: WR | C24: Charlie | D24: Charlie Jones | E24: Jones | F24: -0.25 | G24: 4 | H24: 5500 | I24: 5500 | J24: CIN@NYG | K24: CIN | L24: NYG | Q24: =INDEX(Sheet1!A:B,MATCH(D24,Sheet1!A:A,0),2) -> -1 | R24: MVP - 1.5X Points/AnyFLEX
A25: 108048-201561 | B25: WR | C25: Cole | D25: Cole Burgess | E25: Burgess | G25: 0 | H25: 5000 | I25: 5000 | J25: CIN@NYG | K25: CIN | L25: NYG | Q25: =INDEX(Sheet1!A:B,MATCH(D25,Sheet1!A:A,0),2) -> #N/A | R25: MVP - 1.5X Points/AnyFLEX
A26: 108048-64175 | B26: WR | C26: Hakeem | D26: Hakeem Butler | E26: Butler | G26: 0 | H26: 5000 | I26: 5000 | J26: CIN@NYG | K26: CIN | L26: NYG | Q26: =INDEX(Sheet1!A:B,MATCH(D26,Sheet1!A:A,0),2) -> #N/A | R26: MVP - 1.5X Points/AnyFLEX
A27: 108048-87668 | B27: WR | C27: Shedrick | D27: Shedrick Jackson | E27: Jackson | F27: 0 | G27: 2 | H27: 5000 | I27: 5000 | J27: CIN@NYG | K27: CIN | L27: NYG | Q27: =INDEX(Sheet1!A:B,MATCH(D27,Sheet1!A:A,0),2) -> #N/A | R27: MVP - 1.5X Points/AnyFLEX
A28: 108048-72427 | B28: WR | C28: Kwamie | D28: Kwamie Lassiter II | E28: Lassiter II | F28: 0.69999999 | G28: 1 | H28: 5000 | I28: 5000 | J28: CIN@NYG | K28: CIN | L28: NYG | Q28: =INDEX(Sheet1!A:B,MATCH(D28,Sheet1!A:A,0),2) -> #N/A | R28: MVP - 1.5X Points/AnyFLEX
A29: 108048-103390 | B29: WR | C29: Tre | D29: Tre Mosley | E29: Mosley | G29: 0 | H29: 5000 | I29: 5000 | J29: CIN@NYG | K29: CIN | L29: NYG | Q29: =INDEX(Sheet1!A:B,MATCH(D29,Sheet1!A:A,0),2) -> #N/A | R29: MVP - 1.5X Points/AnyFLEX
A30: 108048-71935 | B30: WR | C30: Kendric | D30: Kendric Pryor | E30: Pryor | G30: 0 | H30: 5000 | I30: 5000 | J30: CIN@NYG | K30: CIN | L30: NYG | Q30: =INDEX(Sheet1!A:B,MATCH(D30,Sheet1!A:A,0),2) -> #N/A | R30: MVP - 1.5X Points/AnyFLEX
A31: 108048-85701 | B31: WR1 | C31: Ja'Marr | D31: Ja'Marr Chase | E31: Chase | F31: 19.960001 | G31: 5 | H31: 17000 | I31: 17000 | J31: CIN@NYG | K31: CIN | L31: NYG | O31: 1 | P31: 9.7 | Q31: =INDEX(Sheet1!A:B,MATCH(D31,Sheet1!A:A,0),2) -> 93.8 | R31: MVP - 1.5X Points/AnyFLEX
A32: 108048-89981 | B32: WR2 | C32: Tee | D32: Tee Higgins | E32: Higgins | F32: 13.066667 | G32: 3 | H32: 13000 | I32: 13000 | J32: CIN@NYG | K32: CIN | L32: NYG | O32: 1 | P32: 11.2 | Q32: =INDEX(Sheet1!A:B,MATCH(D32,Sheet1!A:A,0),2) -> 39.2 | R32: MVP - 1.5X Points/AnyFLEX
A33: 108048-185593 | B33: WR3 | C33: Andrei | D33: Andrei Iosivas | E33: Iosivas | F33: 7.8599998 | G33: 5 | H33: 8500 | I33: 8500 | J33: CIN@NYG | K33: CIN | L33: NYG | O33: 1 | P33: 4.6 | Q33: =INDEX(Sheet1!A:B,MATCH(D33,Sheet1!A:A,0),2) -> 39.3 | R33: MVP - 1.5X Points/AnyFLEX
A34: 108048-12543 | B34: D | C34: New York | D34: New York Giants | E34: Giants | F34: 8.6 | G34: 5 | H34: 8000 | I34: 8000 | J34: CIN@NYG | K34: NYG | L34: CIN | O34: 1 | P34: 7 | Q34: =INDEX(Sheet1!A:B,MATCH(D34,Sheet1!A:A,0),2) -> 43 | R34: MVP - 1.5X Points/AnyFLEX
A35: 108048-55515 | B35: K | C35: Greg | D35: Greg Joseph | E35: Joseph | F35: 11 | G35: 3 | H35: 9000 | I35: 9000 | J35: CIN@NYG | K35: NYG | L35: CIN | P35: 1 | Q35: =INDEX(Sheet1!A:B,MATCH(D35,Sheet1!A:A,0),2) -> 33 | R35: MVP - 1.5X Points/AnyFLEX
A36: 108048-10744 | B36: K | C36: Graham | D36: Graham Gano | E36: Gano | F36: 8 | G36: 1 | H36: 5000 | I36: 5000 | J36: CIN@NYG | K36: NYG | L36: CIN | M36: IR | N36: Hamstring | Q36: =INDEX(Sheet1!A:B,MATCH(D36,Sheet1!A:A,0),2) -> 8 | R36: MVP - 1.5X Points/AnyFLEX
A37: 108048-176119 | B37: K | C37: Jude | D37: Jude McAtamney | E37: McAtamney | G37: 0 | H37: 5000 | I37: 5000 | J37: CIN@NYG | K37: NYG | L37: CIN | Q37: =INDEX(Sheet1!A:B,MATCH(D37,Sheet1!A:A,0),2) -> #N/A | R37: MVP - 1.5X Points/AnyFLEX
A38: 108048-63519 | B38: QB | C38: Daniel | D38: Daniel Jones | E38: Jones | F38: 15.464 | G38: 5 | H38: 14000 | I38: 14000 | J38: CIN@NYG | K38: NYG | L38: CIN | O38: 1 | P38: 12.8 | Q38: =INDEX(Sheet1!A:B,MATCH(D38,Sheet1!A:A,0),2) -> 77.3 | R38: MVP - 1.5X Points/AnyFLEX
A39: 108048-94748 | B39: QB | C39: Tommy | D39: Tommy DeVito | E39: DeVito | F39: 10.726667 | G39: 9 | H39: 5000 | I39: 5000 | J39: CIN@NYG | K39: NYG | L39: CIN | Q39: =INDEX(Sheet1!A:B,MATCH(D39,Sheet1!A:A,0),2) -> #N/A | R39: MVP - 1.5X Points/AnyFLEX
A40: 108048-64051 | B40: QB | C40: Drew | D40: Drew Lock | E40: Lock | F40: 5.3533332 | G40: 6 | H40: 5000 | I40: 5000 | J40: CIN@NYG | K40: NYG | L40: CIN | Q40: =INDEX(Sheet1!A:B,MATCH(D40,Sheet1!A:A,0),2) -> #N/A | R40: MVP - 1.5X Points/AnyFLEX
...

Sheet Sheet1
A1: Joe Burrow | B1: 102.7
A2: Ja'Marr Chase | B2: 93.8
A3: Daniel Jones | B3: 77.3
A4: Malik Nabers | B4: 74.1
A5: Zack Moss | B5: 59
A6: Wan'Dale Robinson | B6: 52.8
A7: Chase Brown | B7: 51.9
A8: Evan McPherson | B8: 48
A9: New York Giants | B9: 43
A10: Devin Singletary | B10: 42.3
A11: Darius Slayton | B11: 39.4
A12: Andrei Iosivas | B12: 39.3
... A35: Charlie Jones | B35: -1
